[{"TimeUTC":"2025-08-07 06:32:53","timestampInMs":1754548373476,"requestPath":"ai-checker-oy8mnk3j4-chris-anzilottis-projects.vercel.app/favicon.ico","requestMethod":"GET","requestQueryString":"","responseStatusCode":-1,"requestId":"ddkgc-1754548368512-f42d79347664","requestUserAgent":"Mozilla/5.0 (Windows NT 10.0; Win64; x64) AppleWebKit/537.36 (KHTML, like Gecko) Chrome/138.0.0.0 Safari/537.36 Edg/138.0.0.0","level":"error","environment":"production","branch":"master","vercelCache":"MISS","type":"lambda","function":"/api/index","host":"ai-checker-oy8mnk3j4-chris-anzilottis-projects.vercel.app","deploymentDomain":"ai-checker-oy8mnk3j4-chris-anzilottis-projects.vercel.app","deploymentId":"dpl_CevT8h1YNj63hdtAytibbLR52ZrV","durationMs":-1,"region":"iad1","maxMemoryUsed":-1,"memorySize":-1,"message":"trap_external>\", line 999, in exec_module\nFile \"<frozen importlib._bootstrap>\", line 488, in _call_with_frames_removed\nFile \"/var/task/api/index.py\", line 24, in <module>\nfrom github_api_scraper import Base, MarkerHit\nFile \"/var/task/github_api_scraper.py\", line 72, in <module>\nBase.metadata.create_all(bind=engine)\nFile \"/var/task/sqlalchemy/sql/schema.py\", line 5924, in create_all\nbind._run_ddl_visitor(\nFile \"/var/task/sqlalchemy/engine/base.py\", line 3245, in _run_ddl_visitor\nwith self.begin() as conn:\n^^^^^^^^^^^^\nFile \"/var/lang/lib/python3.12/contextlib.py\", line 137, in __enter__\nreturn next(self.gen)\n^^^^^^^^^^^^^^\nFile \"/var/task/sqlalchemy/engine/base.py\", line 3235, in begin\nwith self.connect() as conn:\n^^^^^^^^^^^^^^\nFile \"/var/task/sqlalchemy/engine/base.py\", line 3271, in connect\nreturn self._connection_cls(self)\n^^^^^^^^^^^^^^^^^^^^^^^^^^\nFile \"/var/task/sqlalchemy/engine/base.py\", line 145, in __init__\nConnection._handle_dbapi_exception_noconnection(\nFile \"/var/task/sqlalchemy/engine/base.py\", line 2434, in _handle_dbapi_exception_noconnection\nraise sqlalchemy_exception.with_traceback(exc_info[2]) from e\nFile \"/var/task/sqlalchemy/engine/base.py\", line 143, in __init__\nself._dbapi_connection = engine.raw_connection()\n^^^^^^^^^^^^^^^^^^^^^^^\nFile \"/var/task/sqlalchemy/engine/base.py\", line 3295, in raw_connection\nreturn self.pool.connect()\n^^^^^^^^^^^^^^^^^^^\nFile \"/var/task/sqlalchemy/pool/base.py\", line 447, in connect\nreturn _ConnectionFairy._checkout(self)\n^^^^^^^^^^^^^^^^^^^^^^^^^^^^^^^^\nFile \"/var/task/sqlalchemy/pool/base.py\", line 1264, in _checkout\nfairy = _ConnectionRecord.checkout(pool)\n^^^^^^^^^^^^^^^^^^^^^^^^^^^^^^^^\nFile \"/var/task/sqlalchemy/pool/base.py\", line 711, in checkout\nrec = pool._do_get()\n^^^^^^^^^^^^^^\nFile \"/var/task/sqlalchemy/pool/impl.py\", line 177, in _do_get\nwith util.safe_reraise():\n^^^^^^^^^^^^^^^^^^^\nFile \"/var/task/sqlalchemy/util/langhelpers.py\", line 224, in __exit__\nraise exc_value.with_traceback(exc_tb)\nFile \"/var/task/sqlalchemy/pool/impl.py\", line 175, in _do_get\nreturn self._create_connection()\n^^^^^^^^^^^^^^^^^^^^^^^^^\nFile \"/var/task/sqlalchemy/pool/base.py\", line 388, in _create_connection\nreturn _ConnectionRecord(self)\n^^^^^^^^^^^^^^^^^^^^^^^\nFile \"/var/task/sqlalchemy/pool/base.py\", line 673, in __init__\nself.__connect()\nFile \"/var/task/sqlalchemy/pool/base.py\", line 899, in __connect\nwith util.safe_reraise():\n^^^^^^^^^^^^^^^^^^^\nFile \"/var/task/sqlalchemy/util/langhelpers.py\", line 224, in __exit__\nraise exc_value.with_traceback(exc_tb)\nFile \"/var/task/sqlalchemy/pool/base.py\", line 895, in __connect\nself.dbapi_connection = connection = pool._invoke_creator(self)\n^^^^^^^^^^^^^^^^^^^^^^^^^^\nFile \"/var/task/sqlalchemy/engine/create.py\", line 646, in connect\nreturn dialect.connect(*cargs, **cparams)\n^^^^^^^^^^^^^^^^^^^^^^^^^^^^^^^^^^\nFile \"/var/task/sqlalchemy/engine/default.py\", line 626, in connect\nreturn self.loaded_dbapi.connect(*cargs, **cparams)  # type: ignore[no-any-return]  # NOQA: E501\n^^^^^^^^^^^^^^^^^^^^^^^^^^^^^^^^^^^^^^^^^^^^\nFile \"/var/task/psycopg2/__init__.py\", line 122, in connect\nconn = _connect(dsn, connection_factory=connection_factory, **kwasync)\n^^^^^^^^^^^^^^^^^^^^^^^^^^^^^^^^^^^^^^^^^^^^^^^^^^^^^^^^^^^^^^^\nsqlalchemy.exc.OperationalError: (psycopg2.OperationalError) connection to server at \"db.ymmyielhidafnqvbsdra.supabase.co\" (2600:1f18:2e13:9d11:9819:684:a689:9dd9), port 5432 failed: Cannot assign requested address\nIs the server running on that host and accepting TCP/IP connections?\n(Background on this error at: https://sqlalche.me/e/20/e3q8)\nPython process exited with exit status: 1. The logs above can help with debugging the issue.","projectId":"prj_tQqdVztKk9tpelT7m49G7XNyEFrV","traceId":"","sessionId":"","invocationId":"01K21KPX4WGF5DQT5E8AF5JM88","instanceId":"","concurrency":-1},{"TimeUTC":"2025-08-07 06:32:48","timestampInMs":1754548368540,"requestPath":"ai-checker-oy8mnk3j4-chris-anzilottis-projects.vercel.app/favicon.ico","requestMethod":"GET","requestQueryString":"","responseStatusCode":500,"requestId":"ddkgc-1754548368512-f42d79347664","requestUserAgent":"Mozilla/5.0 (Windows NT 10.0; Win64; x64) AppleWebKit/537.36 (KHTML, like Gecko) Chrome/138.0.0.0 Safari/537.36 Edg/138.0.0.0","level":"error","environment":"production","branch":"master","vercelCache":"MISS","type":"lambda","function":"/api/index","host":"ai-checker-oy8mnk3j4-chris-anzilottis-projects.vercel.app","deploymentDomain":"ai-checker-oy8mnk3j4-chris-anzilottis-projects.vercel.app","deploymentId":"dpl_CevT8h1YNj63hdtAytibbLR52ZrV","durationMs":4917,"region":"iad1","maxMemoryUsed":239,"memorySize":2048,"message":"","projectId":"prj_tQqdVztKk9tpelT7m49G7XNyEFrV","traceId":"","sessionId":"","invocationId":"01K21KPX4WGF5DQT5E8AF5JM88","instanceId":"","concurrency":1},{"TimeUTC":"2025-08-07 06:32:48","timestampInMs":1754548368448,"requestPath":"ai-checker-oy8mnk3j4-chris-anzilottis-projects.vercel.app/","requestMethod":"GET","requestQueryString":"","responseStatusCode":-1,"requestId":"wtdbp-1754548363572-7da6bdb4c24e","requestUserAgent":"Mozilla/5.0 (Windows NT 10.0; Win64; x64) AppleWebKit/537.36 (KHTML, like Gecko) Chrome/138.0.0.0 Safari/537.36 Edg/138.0.0.0","level":"error","environment":"production","branch":"master","vercelCache":"MISS","type":"lambda","function":"/api/index","host":"ai-checker-oy8mnk3j4-chris-anzilottis-projects.vercel.app","deploymentDomain":"ai-checker-oy8mnk3j4-chris-anzilottis-projects.vercel.app","deploymentId":"dpl_CevT8h1YNj63hdtAytibbLR52ZrV","durationMs":-1,"region":"iad1","maxMemoryUsed":-1,"memorySize":-1,"message":"trap_external>\", line 999, in exec_module\nFile \"<frozen importlib._bootstrap>\", line 488, in _call_with_frames_removed\nFile \"/var/task/api/index.py\", line 24, in <module>\nfrom github_api_scraper import Base, MarkerHit\nFile \"/var/task/github_api_scraper.py\", line 72, in <module>\nBase.metadata.create_all(bind=engine)\nFile \"/var/task/sqlalchemy/sql/schema.py\", line 5924, in create_all\nbind._run_ddl_visitor(\nFile \"/var/task/sqlalchemy/engine/base.py\", line 3245, in _run_ddl_visitor\nwith self.begin() as conn:\n^^^^^^^^^^^^\nFile \"/var/lang/lib/python3.12/contextlib.py\", line 137, in __enter__\nreturn next(self.gen)\n^^^^^^^^^^^^^^\nFile \"/var/task/sqlalchemy/engine/base.py\", line 3235, in begin\nwith self.connect() as conn:\n^^^^^^^^^^^^^^\nFile \"/var/task/sqlalchemy/engine/base.py\", line 3271, in connect\nreturn self._connection_cls(self)\n^^^^^^^^^^^^^^^^^^^^^^^^^^\nFile \"/var/task/sqlalchemy/engine/base.py\", line 145, in __init__\nConnection._handle_dbapi_exception_noconnection(\nFile \"/var/task/sqlalchemy/engine/base.py\", line 2434, in _handle_dbapi_exception_noconnection\nraise sqlalchemy_exception.with_traceback(exc_info[2]) from e\nFile \"/var/task/sqlalchemy/engine/base.py\", line 143, in __init__\nself._dbapi_connection = engine.raw_connection()\n^^^^^^^^^^^^^^^^^^^^^^^\nFile \"/var/task/sqlalchemy/engine/base.py\", line 3295, in raw_connection\nreturn self.pool.connect()\n^^^^^^^^^^^^^^^^^^^\nFile \"/var/task/sqlalchemy/pool/base.py\", line 447, in connect\nreturn _ConnectionFairy._checkout(self)\n^^^^^^^^^^^^^^^^^^^^^^^^^^^^^^^^\nFile \"/var/task/sqlalchemy/pool/base.py\", line 1264, in _checkout\nfairy = _ConnectionRecord.checkout(pool)\n^^^^^^^^^^^^^^^^^^^^^^^^^^^^^^^^\nFile \"/var/task/sqlalchemy/pool/base.py\", line 711, in checkout\nrec = pool._do_get()\n^^^^^^^^^^^^^^\nFile \"/var/task/sqlalchemy/pool/impl.py\", line 177, in _do_get\nwith util.safe_reraise():\n^^^^^^^^^^^^^^^^^^^\nFile \"/var/task/sqlalchemy/util/langhelpers.py\", line 224, in __exit__\nraise exc_value.with_traceback(exc_tb)\nFile \"/var/task/sqlalchemy/pool/impl.py\", line 175, in _do_get\nreturn self._create_connection()\n^^^^^^^^^^^^^^^^^^^^^^^^^\nFile \"/var/task/sqlalchemy/pool/base.py\", line 388, in _create_connection\nreturn _ConnectionRecord(self)\n^^^^^^^^^^^^^^^^^^^^^^^\nFile \"/var/task/sqlalchemy/pool/base.py\", line 673, in __init__\nself.__connect()\nFile \"/var/task/sqlalchemy/pool/base.py\", line 899, in __connect\nwith util.safe_reraise():\n^^^^^^^^^^^^^^^^^^^\nFile \"/var/task/sqlalchemy/util/langhelpers.py\", line 224, in __exit__\nraise exc_value.with_traceback(exc_tb)\nFile \"/var/task/sqlalchemy/pool/base.py\", line 895, in __connect\nself.dbapi_connection = connection = pool._invoke_creator(self)\n^^^^^^^^^^^^^^^^^^^^^^^^^^\nFile \"/var/task/sqlalchemy/engine/create.py\", line 646, in connect\nreturn dialect.connect(*cargs, **cparams)\n^^^^^^^^^^^^^^^^^^^^^^^^^^^^^^^^^^\nFile \"/var/task/sqlalchemy/engine/default.py\", line 626, in connect\nreturn self.loaded_dbapi.connect(*cargs, **cparams)  # type: ignore[no-any-return]  # NOQA: E501\n^^^^^^^^^^^^^^^^^^^^^^^^^^^^^^^^^^^^^^^^^^^^\nFile \"/var/task/psycopg2/__init__.py\", line 122, in connect\nconn = _connect(dsn, connection_factory=connection_factory, **kwasync)\n^^^^^^^^^^^^^^^^^^^^^^^^^^^^^^^^^^^^^^^^^^^^^^^^^^^^^^^^^^^^^^^\nsqlalchemy.exc.OperationalError: (psycopg2.OperationalError) connection to server at \"db.ymmyielhidafnqvbsdra.supabase.co\" (2600:1f18:2e13:9d11:9819:684:a689:9dd9), port 5432 failed: Cannot assign requested address\nIs the server running on that host and accepting TCP/IP connections?\n(Background on this error at: https://sqlalche.me/e/20/e3q8)\nPython process exited with exit status: 1. The logs above can help with debugging the issue.","projectId":"prj_tQqdVztKk9tpelT7m49G7XNyEFrV","traceId":"","sessionId":"","invocationId":"01K21KPRA3FPT0F7AK0FFS44JA","instanceId":"","concurrency":-1},{"TimeUTC":"2025-08-07 06:32:43","timestampInMs":1754548363587,"requestPath":"ai-checker-oy8mnk3j4-chris-anzilottis-projects.vercel.app/","requestMethod":"GET","requestQueryString":"","responseStatusCode":500,"requestId":"wtdbp-1754548363572-7da6bdb4c24e","requestUserAgent":"Mozilla/5.0 (Windows NT 10.0; Win64; x64) AppleWebKit/537.36 (KHTML, like Gecko) Chrome/138.0.0.0 Safari/537.36 Edg/138.0.0.0","level":"error","environment":"production","branch":"master","vercelCache":"MISS","type":"lambda","function":"/api/index","host":"ai-checker-oy8mnk3j4-chris-anzilottis-projects.vercel.app","deploymentDomain":"ai-checker-oy8mnk3j4-chris-anzilottis-projects.vercel.app","deploymentId":"dpl_CevT8h1YNj63hdtAytibbLR52ZrV","durationMs":4845,"region":"iad1","maxMemoryUsed":239,"memorySize":2048,"message":"","projectId":"prj_tQqdVztKk9tpelT7m49G7XNyEFrV","traceId":"","sessionId":"","invocationId":"01K21KPRA3FPT0F7AK0FFS44JA","instanceId":"","concurrency":1},{"TimeUTC":"2025-08-07 06:32:37","timestampInMs":1754548357686,"requestPath":"ai-checker-oy8mnk3j4-chris-anzilottis-projects.vercel.app/favicon.png","requestMethod":"GET","requestQueryString":"","responseStatusCode":-1,"requestId":"z5xm2-1754548352614-6fc41eab32ed","requestUserAgent":"vercel-favicon/1.0","level":"error","environment":"production","branch":"master","vercelCache":"MISS","type":"lambda","function":"/api/index","host":"ai-checker-oy8mnk3j4-chris-anzilottis-projects.vercel.app","deploymentDomain":"ai-checker-oy8mnk3j4-chris-anzilottis-projects.vercel.app","deploymentId":"dpl_CevT8h1YNj63hdtAytibbLR52ZrV","durationMs":-1,"region":"iad1","maxMemoryUsed":-1,"memorySize":-1,"message":"trap_external>\", line 999, in exec_module\nFile \"<frozen importlib._bootstrap>\", line 488, in _call_with_frames_removed\nFile \"/var/task/api/index.py\", line 24, in <module>\nfrom github_api_scraper import Base, MarkerHit\nFile \"/var/task/github_api_scraper.py\", line 72, in <module>\nBase.metadata.create_all(bind=engine)\nFile \"/var/task/sqlalchemy/sql/schema.py\", line 5924, in create_all\nbind._run_ddl_visitor(\nFile \"/var/task/sqlalchemy/engine/base.py\", line 3245, in _run_ddl_visitor\nwith self.begin() as conn:\n^^^^^^^^^^^^\nFile \"/var/lang/lib/python3.12/contextlib.py\", line 137, in __enter__\nreturn next(self.gen)\n^^^^^^^^^^^^^^\nFile \"/var/task/sqlalchemy/engine/base.py\", line 3235, in begin\nwith self.connect() as conn:\n^^^^^^^^^^^^^^\nFile \"/var/task/sqlalchemy/engine/base.py\", line 3271, in connect\nreturn self._connection_cls(self)\n^^^^^^^^^^^^^^^^^^^^^^^^^^\nFile \"/var/task/sqlalchemy/engine/base.py\", line 145, in __init__\nConnection._handle_dbapi_exception_noconnection(\nFile \"/var/task/sqlalchemy/engine/base.py\", line 2434, in _handle_dbapi_exception_noconnection\nraise sqlalchemy_exception.with_traceback(exc_info[2]) from e\nFile \"/var/task/sqlalchemy/engine/base.py\", line 143, in __init__\nself._dbapi_connection = engine.raw_connection()\n^^^^^^^^^^^^^^^^^^^^^^^\nFile \"/var/task/sqlalchemy/engine/base.py\", line 3295, in raw_connection\nreturn self.pool.connect()\n^^^^^^^^^^^^^^^^^^^\nFile \"/var/task/sqlalchemy/pool/base.py\", line 447, in connect\nreturn _ConnectionFairy._checkout(self)\n^^^^^^^^^^^^^^^^^^^^^^^^^^^^^^^^\nFile \"/var/task/sqlalchemy/pool/base.py\", line 1264, in _checkout\nfairy = _ConnectionRecord.checkout(pool)\n^^^^^^^^^^^^^^^^^^^^^^^^^^^^^^^^\nFile \"/var/task/sqlalchemy/pool/base.py\", line 711, in checkout\nrec = pool._do_get()\n^^^^^^^^^^^^^^\nFile \"/var/task/sqlalchemy/pool/impl.py\", line 177, in _do_get\nwith util.safe_reraise():\n^^^^^^^^^^^^^^^^^^^\nFile \"/var/task/sqlalchemy/util/langhelpers.py\", line 224, in __exit__\nraise exc_value.with_traceback(exc_tb)\nFile \"/var/task/sqlalchemy/pool/impl.py\", line 175, in _do_get\nreturn self._create_connection()\n^^^^^^^^^^^^^^^^^^^^^^^^^\nFile \"/var/task/sqlalchemy/pool/base.py\", line 388, in _create_connection\nreturn _ConnectionRecord(self)\n^^^^^^^^^^^^^^^^^^^^^^^\nFile \"/var/task/sqlalchemy/pool/base.py\", line 673, in __init__\nself.__connect()\nFile \"/var/task/sqlalchemy/pool/base.py\", line 899, in __connect\nwith util.safe_reraise():\n^^^^^^^^^^^^^^^^^^^\nFile \"/var/task/sqlalchemy/util/langhelpers.py\", line 224, in __exit__\nraise exc_value.with_traceback(exc_tb)\nFile \"/var/task/sqlalchemy/pool/base.py\", line 895, in __connect\nself.dbapi_connection = connection = pool._invoke_creator(self)\n^^^^^^^^^^^^^^^^^^^^^^^^^^\nFile \"/var/task/sqlalchemy/engine/create.py\", line 646, in connect\nreturn dialect.connect(*cargs, **cparams)\n^^^^^^^^^^^^^^^^^^^^^^^^^^^^^^^^^^\nFile \"/var/task/sqlalchemy/engine/default.py\", line 626, in connect\nreturn self.loaded_dbapi.connect(*cargs, **cparams)  # type: ignore[no-any-return]  # NOQA: E501\n^^^^^^^^^^^^^^^^^^^^^^^^^^^^^^^^^^^^^^^^^^^^\nFile \"/var/task/psycopg2/__init__.py\", line 122, in connect\nconn = _connect(dsn, connection_factory=connection_factory, **kwasync)\n^^^^^^^^^^^^^^^^^^^^^^^^^^^^^^^^^^^^^^^^^^^^^^^^^^^^^^^^^^^^^^^\nsqlalchemy.exc.OperationalError: (psycopg2.OperationalError) connection to server at \"db.ymmyielhidafnqvbsdra.supabase.co\" (2600:1f18:2e13:9d11:9819:684:a689:9dd9), port 5432 failed: Cannot assign requested address\nIs the server running on that host and accepting TCP/IP connections?\n(Background on this error at: https://sqlalche.me/e/20/e3q8)\nPython process exited with exit status: 1. The logs above can help with debugging the issue.","projectId":"prj_tQqdVztKk9tpelT7m49G7XNyEFrV","traceId":"","sessionId":"","invocationId":"01K21KPDMSN0410YHW09PN8THA","instanceId":"","concurrency":-1},{"TimeUTC":"2025-08-07 06:32:37","timestampInMs":1754548357335,"requestPath":"ai-checker-git-master-chris-anzilottis-projects.vercel.app/favicon.ico","requestMethod":"GET","requestQueryString":"","responseStatusCode":-1,"requestId":"gq5p7-1754548351415-c6b4e69dffa6","requestUserAgent":"Mozilla/5.0 (Windows NT 10.0; Win64; x64) AppleWebKit/537.36 (KHTML, like Gecko) Chrome/138.0.0.0 Safari/537.36 Edg/138.0.0.0","level":"error","environment":"production","branch":"master","vercelCache":"MISS","type":"lambda","function":"/api/index","host":"ai-checker-git-master-chris-anzilottis-projects.vercel.app","deploymentDomain":"ai-checker-git-master-chris-anzilottis-projects.vercel.app","deploymentId":"dpl_CevT8h1YNj63hdtAytibbLR52ZrV","durationMs":-1,"region":"iad1","maxMemoryUsed":-1,"memorySize":-1,"message":"trap_external>\", line 999, in exec_module\nFile \"<frozen importlib._bootstrap>\", line 488, in _call_with_frames_removed\nFile \"/var/task/api/index.py\", line 24, in <module>\nfrom github_api_scraper import Base, MarkerHit\nFile \"/var/task/github_api_scraper.py\", line 72, in <module>\nBase.metadata.create_all(bind=engine)\nFile \"/var/task/sqlalchemy/sql/schema.py\", line 5924, in create_all\nbind._run_ddl_visitor(\nFile \"/var/task/sqlalchemy/engine/base.py\", line 3245, in _run_ddl_visitor\nwith self.begin() as conn:\n^^^^^^^^^^^^\nFile \"/var/lang/lib/python3.12/contextlib.py\", line 137, in __enter__\nreturn next(self.gen)\n^^^^^^^^^^^^^^\nFile \"/var/task/sqlalchemy/engine/base.py\", line 3235, in begin\nwith self.connect() as conn:\n^^^^^^^^^^^^^^\nFile \"/var/task/sqlalchemy/engine/base.py\", line 3271, in connect\nreturn self._connection_cls(self)\n^^^^^^^^^^^^^^^^^^^^^^^^^^\nFile \"/var/task/sqlalchemy/engine/base.py\", line 145, in __init__\nConnection._handle_dbapi_exception_noconnection(\nFile \"/var/task/sqlalchemy/engine/base.py\", line 2434, in _handle_dbapi_exception_noconnection\nraise sqlalchemy_exception.with_traceback(exc_info[2]) from e\nFile \"/var/task/sqlalchemy/engine/base.py\", line 143, in __init__\nself._dbapi_connection = engine.raw_connection()\n^^^^^^^^^^^^^^^^^^^^^^^\nFile \"/var/task/sqlalchemy/engine/base.py\", line 3295, in raw_connection\nreturn self.pool.connect()\n^^^^^^^^^^^^^^^^^^^\nFile \"/var/task/sqlalchemy/pool/base.py\", line 447, in connect\nreturn _ConnectionFairy._checkout(self)\n^^^^^^^^^^^^^^^^^^^^^^^^^^^^^^^^\nFile \"/var/task/sqlalchemy/pool/base.py\", line 1264, in _checkout\nfairy = _ConnectionRecord.checkout(pool)\n^^^^^^^^^^^^^^^^^^^^^^^^^^^^^^^^\nFile \"/var/task/sqlalchemy/pool/base.py\", line 711, in checkout\nrec = pool._do_get()\n^^^^^^^^^^^^^^\nFile \"/var/task/sqlalchemy/pool/impl.py\", line 177, in _do_get\nwith util.safe_reraise():\n^^^^^^^^^^^^^^^^^^^\nFile \"/var/task/sqlalchemy/util/langhelpers.py\", line 224, in __exit__\nraise exc_value.with_traceback(exc_tb)\nFile \"/var/task/sqlalchemy/pool/impl.py\", line 175, in _do_get\nreturn self._create_connection()\n^^^^^^^^^^^^^^^^^^^^^^^^^\nFile \"/var/task/sqlalchemy/pool/base.py\", line 388, in _create_connection\nreturn _ConnectionRecord(self)\n^^^^^^^^^^^^^^^^^^^^^^^\nFile \"/var/task/sqlalchemy/pool/base.py\", line 673, in __init__\nself.__connect()\nFile \"/var/task/sqlalchemy/pool/base.py\", line 899, in __connect\nwith util.safe_reraise():\n^^^^^^^^^^^^^^^^^^^\nFile \"/var/task/sqlalchemy/util/langhelpers.py\", line 224, in __exit__\nraise exc_value.with_traceback(exc_tb)\nFile \"/var/task/sqlalchemy/pool/base.py\", line 895, in __connect\nself.dbapi_connection = connection = pool._invoke_creator(self)\n^^^^^^^^^^^^^^^^^^^^^^^^^^\nFile \"/var/task/sqlalchemy/engine/create.py\", line 646, in connect\nreturn dialect.connect(*cargs, **cparams)\n^^^^^^^^^^^^^^^^^^^^^^^^^^^^^^^^^^\nFile \"/var/task/sqlalchemy/engine/default.py\", line 626, in connect\nreturn self.loaded_dbapi.connect(*cargs, **cparams)  # type: ignore[no-any-return]  # NOQA: E501\n^^^^^^^^^^^^^^^^^^^^^^^^^^^^^^^^^^^^^^^^^^^^\nFile \"/var/task/psycopg2/__init__.py\", line 122, in connect\nconn = _connect(dsn, connection_factory=connection_factory, **kwasync)\n^^^^^^^^^^^^^^^^^^^^^^^^^^^^^^^^^^^^^^^^^^^^^^^^^^^^^^^^^^^^^^^\nsqlalchemy.exc.OperationalError: (psycopg2.OperationalError) connection to server at \"db.ymmyielhidafnqvbsdra.supabase.co\" (2600:1f18:2e13:9d11:9819:684:a689:9dd9), port 5432 failed: Cannot assign requested address\nIs the server running on that host and accepting TCP/IP connections?\n(Background on this error at: https://sqlalche.me/e/20/e3q8)\nPython process exited with exit status: 1. The logs above can help with debugging the issue.","projectId":"prj_tQqdVztKk9tpelT7m49G7XNyEFrV","traceId":"","sessionId":"","invocationId":"01K21KPCESWKQS7BQKBJJ7F0HM","instanceId":"","concurrency":-1},{"TimeUTC":"2025-08-07 06:32:32","timestampInMs":1754548352665,"requestPath":"ai-checker-oy8mnk3j4-chris-anzilottis-projects.vercel.app/favicon.png","requestMethod":"GET","requestQueryString":"","responseStatusCode":500,"requestId":"z5xm2-1754548352614-6fc41eab32ed","requestUserAgent":"vercel-favicon/1.0","level":"error","environment":"production","branch":"master","vercelCache":"MISS","type":"lambda","function":"/api/index","host":"ai-checker-oy8mnk3j4-chris-anzilottis-projects.vercel.app","deploymentDomain":"ai-checker-oy8mnk3j4-chris-anzilottis-projects.vercel.app","deploymentId":"dpl_CevT8h1YNj63hdtAytibbLR52ZrV","durationMs":5001,"region":"iad1","maxMemoryUsed":239,"memorySize":2048,"message":"","projectId":"prj_tQqdVztKk9tpelT7m49G7XNyEFrV","traceId":"","sessionId":"","invocationId":"01K21KPDMSN0410YHW09PN8THA","instanceId":"","concurrency":1},{"TimeUTC":"2025-08-07 06:32:32","timestampInMs":1754548352576,"requestPath":"ai-checker-oy8mnk3j4-chris-anzilottis-projects.vercel.app/favicon.ico","requestMethod":"GET","requestQueryString":"","responseStatusCode":-1,"requestId":"tthsh-1754548347569-fc743068c6f9","requestUserAgent":"vercel-favicon/1.0","level":"error","environment":"production","branch":"master","vercelCache":"MISS","type":"lambda","function":"/api/index","host":"ai-checker-oy8mnk3j4-chris-anzilottis-projects.vercel.app","deploymentDomain":"ai-checker-oy8mnk3j4-chris-anzilottis-projects.vercel.app","deploymentId":"dpl_CevT8h1YNj63hdtAytibbLR52ZrV","durationMs":-1,"region":"iad1","maxMemoryUsed":-1,"memorySize":-1,"message":"trap_external>\", line 999, in exec_module\nFile \"<frozen importlib._bootstrap>\", line 488, in _call_with_frames_removed\nFile \"/var/task/api/index.py\", line 24, in <module>\nfrom github_api_scraper import Base, MarkerHit\nFile \"/var/task/github_api_scraper.py\", line 72, in <module>\nBase.metadata.create_all(bind=engine)\nFile \"/var/task/sqlalchemy/sql/schema.py\", line 5924, in create_all\nbind._run_ddl_visitor(\nFile \"/var/task/sqlalchemy/engine/base.py\", line 3245, in _run_ddl_visitor\nwith self.begin() as conn:\n^^^^^^^^^^^^\nFile \"/var/lang/lib/python3.12/contextlib.py\", line 137, in __enter__\nreturn next(self.gen)\n^^^^^^^^^^^^^^\nFile \"/var/task/sqlalchemy/engine/base.py\", line 3235, in begin\nwith self.connect() as conn:\n^^^^^^^^^^^^^^\nFile \"/var/task/sqlalchemy/engine/base.py\", line 3271, in connect\nreturn self._connection_cls(self)\n^^^^^^^^^^^^^^^^^^^^^^^^^^\nFile \"/var/task/sqlalchemy/engine/base.py\", line 145, in __init__\nConnection._handle_dbapi_exception_noconnection(\nFile \"/var/task/sqlalchemy/engine/base.py\", line 2434, in _handle_dbapi_exception_noconnection\nraise sqlalchemy_exception.with_traceback(exc_info[2]) from e\nFile \"/var/task/sqlalchemy/engine/base.py\", line 143, in __init__\nself._dbapi_connection = engine.raw_connection()\n^^^^^^^^^^^^^^^^^^^^^^^\nFile \"/var/task/sqlalchemy/engine/base.py\", line 3295, in raw_connection\nreturn self.pool.connect()\n^^^^^^^^^^^^^^^^^^^\nFile \"/var/task/sqlalchemy/pool/base.py\", line 447, in connect\nreturn _ConnectionFairy._checkout(self)\n^^^^^^^^^^^^^^^^^^^^^^^^^^^^^^^^\nFile \"/var/task/sqlalchemy/pool/base.py\", line 1264, in _checkout\nfairy = _ConnectionRecord.checkout(pool)\n^^^^^^^^^^^^^^^^^^^^^^^^^^^^^^^^\nFile \"/var/task/sqlalchemy/pool/base.py\", line 711, in checkout\nrec = pool._do_get()\n^^^^^^^^^^^^^^\nFile \"/var/task/sqlalchemy/pool/impl.py\", line 177, in _do_get\nwith util.safe_reraise():\n^^^^^^^^^^^^^^^^^^^\nFile \"/var/task/sqlalchemy/util/langhelpers.py\", line 224, in __exit__\nraise exc_value.with_traceback(exc_tb)\nFile \"/var/task/sqlalchemy/pool/impl.py\", line 175, in _do_get\nreturn self._create_connection()\n^^^^^^^^^^^^^^^^^^^^^^^^^\nFile \"/var/task/sqlalchemy/pool/base.py\", line 388, in _create_connection\nreturn _ConnectionRecord(self)\n^^^^^^^^^^^^^^^^^^^^^^^\nFile \"/var/task/sqlalchemy/pool/base.py\", line 673, in __init__\nself.__connect()\nFile \"/var/task/sqlalchemy/pool/base.py\", line 899, in __connect\nwith util.safe_reraise():\n^^^^^^^^^^^^^^^^^^^\nFile \"/var/task/sqlalchemy/util/langhelpers.py\", line 224, in __exit__\nraise exc_value.with_traceback(exc_tb)\nFile \"/var/task/sqlalchemy/pool/base.py\", line 895, in __connect\nself.dbapi_connection = connection = pool._invoke_creator(self)\n^^^^^^^^^^^^^^^^^^^^^^^^^^\nFile \"/var/task/sqlalchemy/engine/create.py\", line 646, in connect\nreturn dialect.connect(*cargs, **cparams)\n^^^^^^^^^^^^^^^^^^^^^^^^^^^^^^^^^^\nFile \"/var/task/sqlalchemy/engine/default.py\", line 626, in connect\nreturn self.loaded_dbapi.connect(*cargs, **cparams)  # type: ignore[no-any-return]  # NOQA: E501\n^^^^^^^^^^^^^^^^^^^^^^^^^^^^^^^^^^^^^^^^^^^^\nFile \"/var/task/psycopg2/__init__.py\", line 122, in connect\nconn = _connect(dsn, connection_factory=connection_factory, **kwasync)\n^^^^^^^^^^^^^^^^^^^^^^^^^^^^^^^^^^^^^^^^^^^^^^^^^^^^^^^^^^^^^^^\nsqlalchemy.exc.OperationalError: (psycopg2.OperationalError) connection to server at \"db.ymmyielhidafnqvbsdra.supabase.co\" (2600:1f18:2e13:9d11:9819:684:a689:9dd9), port 5432 failed: Cannot assign requested address\nIs the server running on that host and accepting TCP/IP connections?\n(Background on this error at: https://sqlalche.me/e/20/e3q8)\nPython process exited with exit status: 1. The logs above can help with debugging the issue.","projectId":"prj_tQqdVztKk9tpelT7m49G7XNyEFrV","traceId":"","sessionId":"","invocationId":"01K21KP8PTB102G5XFDC8MZK83","instanceId":"","concurrency":-1},{"TimeUTC":"2025-08-07 06:32:31","timestampInMs":1754548351449,"requestPath":"ai-checker-git-master-chris-anzilottis-projects.vercel.app/favicon.ico","requestMethod":"GET","requestQueryString":"","responseStatusCode":500,"requestId":"gq5p7-1754548351415-c6b4e69dffa6","requestUserAgent":"Mozilla/5.0 (Windows NT 10.0; Win64; x64) AppleWebKit/537.36 (KHTML, like Gecko) Chrome/138.0.0.0 Safari/537.36 Edg/138.0.0.0","level":"error","environment":"production","branch":"master","vercelCache":"MISS","type":"lambda","function":"/api/index","host":"ai-checker-git-master-chris-anzilottis-projects.vercel.app","deploymentDomain":"ai-checker-git-master-chris-anzilottis-projects.vercel.app","deploymentId":"dpl_CevT8h1YNj63hdtAytibbLR52ZrV","durationMs":5863,"region":"iad1","maxMemoryUsed":241,"memorySize":2048,"message":"","projectId":"prj_tQqdVztKk9tpelT7m49G7XNyEFrV","traceId":"","sessionId":"","invocationId":"01K21KPCESWKQS7BQKBJJ7F0HM","instanceId":"","concurrency":1},{"TimeUTC":"2025-08-07 06:32:31","timestampInMs":1754548351302,"requestPath":"ai-checker-git-master-chris-anzilottis-projects.vercel.app/","requestMethod":"GET","requestQueryString":"","responseStatusCode":-1,"requestId":"jdwdb-1754548345469-c177df05a5b9","requestUserAgent":"Mozilla/5.0 (Windows NT 10.0; Win64; x64) AppleWebKit/537.36 (KHTML, like Gecko) Chrome/138.0.0.0 Safari/537.36 Edg/138.0.0.0","level":"error","environment":"production","branch":"master","vercelCache":"MISS","type":"lambda","function":"/api/index","host":"ai-checker-git-master-chris-anzilottis-projects.vercel.app","deploymentDomain":"ai-checker-git-master-chris-anzilottis-projects.vercel.app","deploymentId":"dpl_CevT8h1YNj63hdtAytibbLR52ZrV","durationMs":-1,"region":"iad1","maxMemoryUsed":-1,"memorySize":-1,"message":"trap_external>\", line 999, in exec_module\nFile \"<frozen importlib._bootstrap>\", line 488, in _call_with_frames_removed\nFile \"/var/task/api/index.py\", line 24, in <module>\nfrom github_api_scraper import Base, MarkerHit\nFile \"/var/task/github_api_scraper.py\", line 72, in <module>\nBase.metadata.create_all(bind=engine)\nFile \"/var/task/sqlalchemy/sql/schema.py\", line 5924, in create_all\nbind._run_ddl_visitor(\nFile \"/var/task/sqlalchemy/engine/base.py\", line 3245, in _run_ddl_visitor\nwith self.begin() as conn:\n^^^^^^^^^^^^\nFile \"/var/lang/lib/python3.12/contextlib.py\", line 137, in __enter__\nreturn next(self.gen)\n^^^^^^^^^^^^^^\nFile \"/var/task/sqlalchemy/engine/base.py\", line 3235, in begin\nwith self.connect() as conn:\n^^^^^^^^^^^^^^\nFile \"/var/task/sqlalchemy/engine/base.py\", line 3271, in connect\nreturn self._connection_cls(self)\n^^^^^^^^^^^^^^^^^^^^^^^^^^\nFile \"/var/task/sqlalchemy/engine/base.py\", line 145, in __init__\nConnection._handle_dbapi_exception_noconnection(\nFile \"/var/task/sqlalchemy/engine/base.py\", line 2434, in _handle_dbapi_exception_noconnection\nraise sqlalchemy_exception.with_traceback(exc_info[2]) from e\nFile \"/var/task/sqlalchemy/engine/base.py\", line 143, in __init__\nself._dbapi_connection = engine.raw_connection()\n^^^^^^^^^^^^^^^^^^^^^^^\nFile \"/var/task/sqlalchemy/engine/base.py\", line 3295, in raw_connection\nreturn self.pool.connect()\n^^^^^^^^^^^^^^^^^^^\nFile \"/var/task/sqlalchemy/pool/base.py\", line 447, in connect\nreturn _ConnectionFairy._checkout(self)\n^^^^^^^^^^^^^^^^^^^^^^^^^^^^^^^^\nFile \"/var/task/sqlalchemy/pool/base.py\", line 1264, in _checkout\nfairy = _ConnectionRecord.checkout(pool)\n^^^^^^^^^^^^^^^^^^^^^^^^^^^^^^^^\nFile \"/var/task/sqlalchemy/pool/base.py\", line 711, in checkout\nrec = pool._do_get()\n^^^^^^^^^^^^^^\nFile \"/var/task/sqlalchemy/pool/impl.py\", line 177, in _do_get\nwith util.safe_reraise():\n^^^^^^^^^^^^^^^^^^^\nFile \"/var/task/sqlalchemy/util/langhelpers.py\", line 224, in __exit__\nraise exc_value.with_traceback(exc_tb)\nFile \"/var/task/sqlalchemy/pool/impl.py\", line 175, in _do_get\nreturn self._create_connection()\n^^^^^^^^^^^^^^^^^^^^^^^^^\nFile \"/var/task/sqlalchemy/pool/base.py\", line 388, in _create_connection\nreturn _ConnectionRecord(self)\n^^^^^^^^^^^^^^^^^^^^^^^\nFile \"/var/task/sqlalchemy/pool/base.py\", line 673, in __init__\nself.__connect()\nFile \"/var/task/sqlalchemy/pool/base.py\", line 899, in __connect\nwith util.safe_reraise():\n^^^^^^^^^^^^^^^^^^^\nFile \"/var/task/sqlalchemy/util/langhelpers.py\", line 224, in __exit__\nraise exc_value.with_traceback(exc_tb)\nFile \"/var/task/sqlalchemy/pool/base.py\", line 895, in __connect\nself.dbapi_connection = connection = pool._invoke_creator(self)\n^^^^^^^^^^^^^^^^^^^^^^^^^^\nFile \"/var/task/sqlalchemy/engine/create.py\", line 646, in connect\nreturn dialect.connect(*cargs, **cparams)\n^^^^^^^^^^^^^^^^^^^^^^^^^^^^^^^^^^\nFile \"/var/task/sqlalchemy/engine/default.py\", line 626, in connect\nreturn self.loaded_dbapi.connect(*cargs, **cparams)  # type: ignore[no-any-return]  # NOQA: E501\n^^^^^^^^^^^^^^^^^^^^^^^^^^^^^^^^^^^^^^^^^^^^\nFile \"/var/task/psycopg2/__init__.py\", line 122, in connect\nconn = _connect(dsn, connection_factory=connection_factory, **kwasync)\n^^^^^^^^^^^^^^^^^^^^^^^^^^^^^^^^^^^^^^^^^^^^^^^^^^^^^^^^^^^^^^^\nsqlalchemy.exc.OperationalError: (psycopg2.OperationalError) connection to server at \"db.ymmyielhidafnqvbsdra.supabase.co\" (2600:1f18:2e13:9d11:9819:684:a689:9dd9), port 5432 failed: Cannot assign requested address\nIs the server running on that host and accepting TCP/IP connections?\n(Background on this error at: https://sqlalche.me/e/20/e3q8)\nPython process exited with exit status: 1. The logs above can help with debugging the issue.","projectId":"prj_tQqdVztKk9tpelT7m49G7XNyEFrV","traceId":"","sessionId":"","invocationId":"01K21KP6N149APJDW47CBY0B7E","instanceId":"","concurrency":-1},{"TimeUTC":"2025-08-07 06:32:27","timestampInMs":1754548347610,"requestPath":"ai-checker-oy8mnk3j4-chris-anzilottis-projects.vercel.app/favicon.ico","requestMethod":"GET","requestQueryString":"","responseStatusCode":500,"requestId":"tthsh-1754548347569-fc743068c6f9","requestUserAgent":"vercel-favicon/1.0","level":"error","environment":"production","branch":"master","vercelCache":"MISS","type":"lambda","function":"/api/index","host":"ai-checker-oy8mnk3j4-chris-anzilottis-projects.vercel.app","deploymentDomain":"ai-checker-oy8mnk3j4-chris-anzilottis-projects.vercel.app","deploymentId":"dpl_CevT8h1YNj63hdtAytibbLR52ZrV","durationMs":4948,"region":"iad1","maxMemoryUsed":239,"memorySize":2048,"message":"","projectId":"prj_tQqdVztKk9tpelT7m49G7XNyEFrV","traceId":"","sessionId":"","invocationId":"01K21KP8PTB102G5XFDC8MZK83","instanceId":"","concurrency":1},{"TimeUTC":"2025-08-07 06:32:25","timestampInMs":1754548345525,"requestPath":"ai-checker-oy8mnk3j4-chris-anzilottis-projects.vercel.app/favicon.ico","requestMethod":"GET","requestQueryString":"","responseStatusCode":-1,"requestId":"lkrrf-1754548340456-1bb1a8aeb63f","requestUserAgent":"vercel-favicon/1.0","level":"error","environment":"production","branch":"master","vercelCache":"MISS","type":"lambda","function":"/api/index","host":"ai-checker-oy8mnk3j4-chris-anzilottis-projects.vercel.app","deploymentDomain":"ai-checker-oy8mnk3j4-chris-anzilottis-projects.vercel.app","deploymentId":"dpl_CevT8h1YNj63hdtAytibbLR52ZrV","durationMs":-1,"region":"iad1","maxMemoryUsed":-1,"memorySize":-1,"message":"trap_external>\", line 999, in exec_module\nFile \"<frozen importlib._bootstrap>\", line 488, in _call_with_frames_removed\nFile \"/var/task/api/index.py\", line 24, in <module>\nfrom github_api_scraper import Base, MarkerHit\nFile \"/var/task/github_api_scraper.py\", line 72, in <module>\nBase.metadata.create_all(bind=engine)\nFile \"/var/task/sqlalchemy/sql/schema.py\", line 5924, in create_all\nbind._run_ddl_visitor(\nFile \"/var/task/sqlalchemy/engine/base.py\", line 3245, in _run_ddl_visitor\nwith self.begin() as conn:\n^^^^^^^^^^^^\nFile \"/var/lang/lib/python3.12/contextlib.py\", line 137, in __enter__\nreturn next(self.gen)\n^^^^^^^^^^^^^^\nFile \"/var/task/sqlalchemy/engine/base.py\", line 3235, in begin\nwith self.connect() as conn:\n^^^^^^^^^^^^^^\nFile \"/var/task/sqlalchemy/engine/base.py\", line 3271, in connect\nreturn self._connection_cls(self)\n^^^^^^^^^^^^^^^^^^^^^^^^^^\nFile \"/var/task/sqlalchemy/engine/base.py\", line 145, in __init__\nConnection._handle_dbapi_exception_noconnection(\nFile \"/var/task/sqlalchemy/engine/base.py\", line 2434, in _handle_dbapi_exception_noconnection\nraise sqlalchemy_exception.with_traceback(exc_info[2]) from e\nFile \"/var/task/sqlalchemy/engine/base.py\", line 143, in __init__\nself._dbapi_connection = engine.raw_connection()\n^^^^^^^^^^^^^^^^^^^^^^^\nFile \"/var/task/sqlalchemy/engine/base.py\", line 3295, in raw_connection\nreturn self.pool.connect()\n^^^^^^^^^^^^^^^^^^^\nFile \"/var/task/sqlalchemy/pool/base.py\", line 447, in connect\nreturn _ConnectionFairy._checkout(self)\n^^^^^^^^^^^^^^^^^^^^^^^^^^^^^^^^\nFile \"/var/task/sqlalchemy/pool/base.py\", line 1264, in _checkout\nfairy = _ConnectionRecord.checkout(pool)\n^^^^^^^^^^^^^^^^^^^^^^^^^^^^^^^^\nFile \"/var/task/sqlalchemy/pool/base.py\", line 711, in checkout\nrec = pool._do_get()\n^^^^^^^^^^^^^^\nFile \"/var/task/sqlalchemy/pool/impl.py\", line 177, in _do_get\nwith util.safe_reraise():\n^^^^^^^^^^^^^^^^^^^\nFile \"/var/task/sqlalchemy/util/langhelpers.py\", line 224, in __exit__\nraise exc_value.with_traceback(exc_tb)\nFile \"/var/task/sqlalchemy/pool/impl.py\", line 175, in _do_get\nreturn self._create_connection()\n^^^^^^^^^^^^^^^^^^^^^^^^^\nFile \"/var/task/sqlalchemy/pool/base.py\", line 388, in _create_connection\nreturn _ConnectionRecord(self)\n^^^^^^^^^^^^^^^^^^^^^^^\nFile \"/var/task/sqlalchemy/pool/base.py\", line 673, in __init__\nself.__connect()\nFile \"/var/task/sqlalchemy/pool/base.py\", line 899, in __connect\nwith util.safe_reraise():\n^^^^^^^^^^^^^^^^^^^\nFile \"/var/task/sqlalchemy/util/langhelpers.py\", line 224, in __exit__\nraise exc_value.with_traceback(exc_tb)\nFile \"/var/task/sqlalchemy/pool/base.py\", line 895, in __connect\nself.dbapi_connection = connection = pool._invoke_creator(self)\n^^^^^^^^^^^^^^^^^^^^^^^^^^\nFile \"/var/task/sqlalchemy/engine/create.py\", line 646, in connect\nreturn dialect.connect(*cargs, **cparams)\n^^^^^^^^^^^^^^^^^^^^^^^^^^^^^^^^^^\nFile \"/var/task/sqlalchemy/engine/default.py\", line 626, in connect\nreturn self.loaded_dbapi.connect(*cargs, **cparams)  # type: ignore[no-any-return]  # NOQA: E501\n^^^^^^^^^^^^^^^^^^^^^^^^^^^^^^^^^^^^^^^^^^^^\nFile \"/var/task/psycopg2/__init__.py\", line 122, in connect\nconn = _connect(dsn, connection_factory=connection_factory, **kwasync)\n^^^^^^^^^^^^^^^^^^^^^^^^^^^^^^^^^^^^^^^^^^^^^^^^^^^^^^^^^^^^^^^\nsqlalchemy.exc.OperationalError: (psycopg2.OperationalError) connection to server at \"db.ymmyielhidafnqvbsdra.supabase.co\" (2600:1f18:2e13:9d11:9819:684:a689:9dd9), port 5432 failed: Cannot assign requested address\nIs the server running on that host and accepting TCP/IP connections?\n(Background on this error at: https://sqlalche.me/e/20/e3q8)\nPython process exited with exit status: 1. The logs above can help with debugging the issue.","projectId":"prj_tQqdVztKk9tpelT7m49G7XNyEFrV","traceId":"","sessionId":"","invocationId":"01K21KP1RN0361FTBKV99XBCFP","instanceId":"","concurrency":-1},{"TimeUTC":"2025-08-07 06:32:25","timestampInMs":1754548345505,"requestPath":"ai-checker-git-master-chris-anzilottis-projects.vercel.app/","requestMethod":"GET","requestQueryString":"","responseStatusCode":500,"requestId":"jdwdb-1754548345469-c177df05a5b9","requestUserAgent":"Mozilla/5.0 (Windows NT 10.0; Win64; x64) AppleWebKit/537.36 (KHTML, like Gecko) Chrome/138.0.0.0 Safari/537.36 Edg/138.0.0.0","level":"error","environment":"production","branch":"master","vercelCache":"MISS","type":"lambda","function":"/api/index","host":"ai-checker-git-master-chris-anzilottis-projects.vercel.app","deploymentDomain":"ai-checker-git-master-chris-anzilottis-projects.vercel.app","deploymentId":"dpl_CevT8h1YNj63hdtAytibbLR52ZrV","durationMs":5774,"region":"iad1","maxMemoryUsed":241,"memorySize":2048,"message":"","projectId":"prj_tQqdVztKk9tpelT7m49G7XNyEFrV","traceId":"","sessionId":"","invocationId":"01K21KP6N149APJDW47CBY0B7E","instanceId":"","concurrency":1},{"TimeUTC":"2025-08-07 06:32:23","timestampInMs":1754548343998,"requestPath":"ai-checker-oy8mnk3j4-chris-anzilottis-projects.vercel.app/favicon.ico","requestMethod":"GET","requestQueryString":"","responseStatusCode":-1,"requestId":"fzgjv-1754548331433-34759d280b56","requestUserAgent":"vercel-favicon/1.0","level":"error","environment":"production","branch":"master","vercelCache":"MISS","type":"lambda","function":"/api/index","host":"ai-checker-oy8mnk3j4-chris-anzilottis-projects.vercel.app","deploymentDomain":"ai-checker-oy8mnk3j4-chris-anzilottis-projects.vercel.app","deploymentId":"dpl_CevT8h1YNj63hdtAytibbLR52ZrV","durationMs":-1,"region":"iad1","maxMemoryUsed":-1,"memorySize":-1,"message":"trap_external>\", line 999, in exec_module\nFile \"<frozen importlib._bootstrap>\", line 488, in _call_with_frames_removed\nFile \"/var/task/api/index.py\", line 24, in <module>\nfrom github_api_scraper import Base, MarkerHit\nFile \"/var/task/github_api_scraper.py\", line 72, in <module>\nBase.metadata.create_all(bind=engine)\nFile \"/var/task/sqlalchemy/sql/schema.py\", line 5924, in create_all\nbind._run_ddl_visitor(\nFile \"/var/task/sqlalchemy/engine/base.py\", line 3245, in _run_ddl_visitor\nwith self.begin() as conn:\n^^^^^^^^^^^^\nFile \"/var/lang/lib/python3.12/contextlib.py\", line 137, in __enter__\nreturn next(self.gen)\n^^^^^^^^^^^^^^\nFile \"/var/task/sqlalchemy/engine/base.py\", line 3235, in begin\nwith self.connect() as conn:\n^^^^^^^^^^^^^^\nFile \"/var/task/sqlalchemy/engine/base.py\", line 3271, in connect\nreturn self._connection_cls(self)\n^^^^^^^^^^^^^^^^^^^^^^^^^^\nFile \"/var/task/sqlalchemy/engine/base.py\", line 145, in __init__\nConnection._handle_dbapi_exception_noconnection(\nFile \"/var/task/sqlalchemy/engine/base.py\", line 2434, in _handle_dbapi_exception_noconnection\nraise sqlalchemy_exception.with_traceback(exc_info[2]) from e\nFile \"/var/task/sqlalchemy/engine/base.py\", line 143, in __init__\nself._dbapi_connection = engine.raw_connection()\n^^^^^^^^^^^^^^^^^^^^^^^\nFile \"/var/task/sqlalchemy/engine/base.py\", line 3295, in raw_connection\nreturn self.pool.connect()\n^^^^^^^^^^^^^^^^^^^\nFile \"/var/task/sqlalchemy/pool/base.py\", line 447, in connect\nreturn _ConnectionFairy._checkout(self)\n^^^^^^^^^^^^^^^^^^^^^^^^^^^^^^^^\nFile \"/var/task/sqlalchemy/pool/base.py\", line 1264, in _checkout\nfairy = _ConnectionRecord.checkout(pool)\n^^^^^^^^^^^^^^^^^^^^^^^^^^^^^^^^\nFile \"/var/task/sqlalchemy/pool/base.py\", line 711, in checkout\nrec = pool._do_get()\n^^^^^^^^^^^^^^\nFile \"/var/task/sqlalchemy/pool/impl.py\", line 177, in _do_get\nwith util.safe_reraise():\n^^^^^^^^^^^^^^^^^^^\nFile \"/var/task/sqlalchemy/util/langhelpers.py\", line 224, in __exit__\nraise exc_value.with_traceback(exc_tb)\nFile \"/var/task/sqlalchemy/pool/impl.py\", line 175, in _do_get\nreturn self._create_connection()\n^^^^^^^^^^^^^^^^^^^^^^^^^\nFile \"/var/task/sqlalchemy/pool/base.py\", line 388, in _create_connection\nreturn _ConnectionRecord(self)\n^^^^^^^^^^^^^^^^^^^^^^^\nFile \"/var/task/sqlalchemy/pool/base.py\", line 673, in __init__\nself.__connect()\nFile \"/var/task/sqlalchemy/pool/base.py\", line 899, in __connect\nwith util.safe_reraise():\n^^^^^^^^^^^^^^^^^^^\nFile \"/var/task/sqlalchemy/util/langhelpers.py\", line 224, in __exit__\nraise exc_value.with_traceback(exc_tb)\nFile \"/var/task/sqlalchemy/pool/base.py\", line 895, in __connect\nself.dbapi_connection = connection = pool._invoke_creator(self)\n^^^^^^^^^^^^^^^^^^^^^^^^^^\nFile \"/var/task/sqlalchemy/engine/create.py\", line 646, in connect\nreturn dialect.connect(*cargs, **cparams)\n^^^^^^^^^^^^^^^^^^^^^^^^^^^^^^^^^^\nFile \"/var/task/sqlalchemy/engine/default.py\", line 626, in connect\nreturn self.loaded_dbapi.connect(*cargs, **cparams)  # type: ignore[no-any-return]  # NOQA: E501\n^^^^^^^^^^^^^^^^^^^^^^^^^^^^^^^^^^^^^^^^^^^^\nFile \"/var/task/psycopg2/__init__.py\", line 122, in connect\nconn = _connect(dsn, connection_factory=connection_factory, **kwasync)\n^^^^^^^^^^^^^^^^^^^^^^^^^^^^^^^^^^^^^^^^^^^^^^^^^^^^^^^^^^^^^^^\nsqlalchemy.exc.OperationalError: (psycopg2.OperationalError) connection to server at \"db.ymmyielhidafnqvbsdra.supabase.co\" (2600:1f18:2e13:9d11:9819:684:a689:9dd9), port 5432 failed: Cannot assign requested address\nIs the server running on that host and accepting TCP/IP connections?\n(Background on this error at: https://sqlalche.me/e/20/e3q8)\nPython process exited with exit status: 1. The logs above can help with debugging the issue.","projectId":"prj_tQqdVztKk9tpelT7m49G7XNyEFrV","traceId":"","sessionId":"","invocationId":"01K21KNRYJ7NHGNSA2PM5R3X67","instanceId":"","concurrency":-1},{"TimeUTC":"2025-08-07 06:32:21","timestampInMs":1754548341764,"requestPath":"ai-checker-oy8mnk3j4-chris-anzilottis-projects.vercel.app/","requestMethod":"GET","requestQueryString":"","responseStatusCode":-1,"requestId":"d4ccd-1754548328506-11020a6aa571","requestUserAgent":"vercel-screenshot/1.0","level":"error","environment":"production","branch":"master","vercelCache":"MISS","type":"lambda","function":"/api/index","host":"ai-checker-oy8mnk3j4-chris-anzilottis-projects.vercel.app","deploymentDomain":"ai-checker-oy8mnk3j4-chris-anzilottis-projects.vercel.app","deploymentId":"dpl_CevT8h1YNj63hdtAytibbLR52ZrV","durationMs":-1,"region":"iad1","maxMemoryUsed":-1,"memorySize":-1,"message":"trap_external>\", line 999, in exec_module\nFile \"<frozen importlib._bootstrap>\", line 488, in _call_with_frames_removed\nFile \"/var/task/api/index.py\", line 24, in <module>\nfrom github_api_scraper import Base, MarkerHit\nFile \"/var/task/github_api_scraper.py\", line 72, in <module>\nBase.metadata.create_all(bind=engine)\nFile \"/var/task/sqlalchemy/sql/schema.py\", line 5924, in create_all\nbind._run_ddl_visitor(\nFile \"/var/task/sqlalchemy/engine/base.py\", line 3245, in _run_ddl_visitor\nwith self.begin() as conn:\n^^^^^^^^^^^^\nFile \"/var/lang/lib/python3.12/contextlib.py\", line 137, in __enter__\nreturn next(self.gen)\n^^^^^^^^^^^^^^\nFile \"/var/task/sqlalchemy/engine/base.py\", line 3235, in begin\nwith self.connect() as conn:\n^^^^^^^^^^^^^^\nFile \"/var/task/sqlalchemy/engine/base.py\", line 3271, in connect\nreturn self._connection_cls(self)\n^^^^^^^^^^^^^^^^^^^^^^^^^^\nFile \"/var/task/sqlalchemy/engine/base.py\", line 145, in __init__\nConnection._handle_dbapi_exception_noconnection(\nFile \"/var/task/sqlalchemy/engine/base.py\", line 2434, in _handle_dbapi_exception_noconnection\nraise sqlalchemy_exception.with_traceback(exc_info[2]) from e\nFile \"/var/task/sqlalchemy/engine/base.py\", line 143, in __init__\nself._dbapi_connection = engine.raw_connection()\n^^^^^^^^^^^^^^^^^^^^^^^\nFile \"/var/task/sqlalchemy/engine/base.py\", line 3295, in raw_connection\nreturn self.pool.connect()\n^^^^^^^^^^^^^^^^^^^\nFile \"/var/task/sqlalchemy/pool/base.py\", line 447, in connect\nreturn _ConnectionFairy._checkout(self)\n^^^^^^^^^^^^^^^^^^^^^^^^^^^^^^^^\nFile \"/var/task/sqlalchemy/pool/base.py\", line 1264, in _checkout\nfairy = _ConnectionRecord.checkout(pool)\n^^^^^^^^^^^^^^^^^^^^^^^^^^^^^^^^\nFile \"/var/task/sqlalchemy/pool/base.py\", line 711, in checkout\nrec = pool._do_get()\n^^^^^^^^^^^^^^\nFile \"/var/task/sqlalchemy/pool/impl.py\", line 177, in _do_get\nwith util.safe_reraise():\n^^^^^^^^^^^^^^^^^^^\nFile \"/var/task/sqlalchemy/util/langhelpers.py\", line 224, in __exit__\nraise exc_value.with_traceback(exc_tb)\nFile \"/var/task/sqlalchemy/pool/impl.py\", line 175, in _do_get\nreturn self._create_connection()\n^^^^^^^^^^^^^^^^^^^^^^^^^\nFile \"/var/task/sqlalchemy/pool/base.py\", line 388, in _create_connection\nreturn _ConnectionRecord(self)\n^^^^^^^^^^^^^^^^^^^^^^^\nFile \"/var/task/sqlalchemy/pool/base.py\", line 673, in __init__\nself.__connect()\nFile \"/var/task/sqlalchemy/pool/base.py\", line 899, in __connect\nwith util.safe_reraise():\n^^^^^^^^^^^^^^^^^^^\nFile \"/var/task/sqlalchemy/util/langhelpers.py\", line 224, in __exit__\nraise exc_value.with_traceback(exc_tb)\nFile \"/var/task/sqlalchemy/pool/base.py\", line 895, in __connect\nself.dbapi_connection = connection = pool._invoke_creator(self)\n^^^^^^^^^^^^^^^^^^^^^^^^^^\nFile \"/var/task/sqlalchemy/engine/create.py\", line 646, in connect\nreturn dialect.connect(*cargs, **cparams)\n^^^^^^^^^^^^^^^^^^^^^^^^^^^^^^^^^^\nFile \"/var/task/sqlalchemy/engine/default.py\", line 626, in connect\nreturn self.loaded_dbapi.connect(*cargs, **cparams)  # type: ignore[no-any-return]  # NOQA: E501\n^^^^^^^^^^^^^^^^^^^^^^^^^^^^^^^^^^^^^^^^^^^^\nFile \"/var/task/psycopg2/__init__.py\", line 122, in connect\nconn = _connect(dsn, connection_factory=connection_factory, **kwasync)\n^^^^^^^^^^^^^^^^^^^^^^^^^^^^^^^^^^^^^^^^^^^^^^^^^^^^^^^^^^^^^^^\nsqlalchemy.exc.OperationalError: (psycopg2.OperationalError) connection to server at \"db.ymmyielhidafnqvbsdra.supabase.co\" (2600:1f18:2e13:9d11:9819:684:a689:9dd9), port 5432 failed: Cannot assign requested address\nIs the server running on that host and accepting TCP/IP connections?\n(Background on this error at: https://sqlalche.me/e/20/e3q8)\nPython process exited with exit status: 1. The logs above can help with debugging the issue.","projectId":"prj_tQqdVztKk9tpelT7m49G7XNyEFrV","traceId":"","sessionId":"","invocationId":"01K21KNP3MN9D7A0PK9KKYBTTK","instanceId":"","concurrency":-1},{"TimeUTC":"2025-08-07 06:32:21","timestampInMs":1754548341566,"requestPath":"ai-checker-psi.vercel.app/","requestMethod":"GET","requestQueryString":"","responseStatusCode":-1,"requestId":"w849m-1754548328847-de941ad3af76","requestUserAgent":"Mozilla/5.0 (Windows NT 10.0; Win64; x64) AppleWebKit/537.36 (KHTML, like Gecko) Chrome/138.0.0.0 Safari/537.36 Edg/138.0.0.0","level":"error","environment":"production","branch":"master","vercelCache":"MISS","type":"lambda","function":"/api/index","host":"ai-checker-psi.vercel.app","deploymentDomain":"ai-checker-psi.vercel.app","deploymentId":"dpl_CevT8h1YNj63hdtAytibbLR52ZrV","durationMs":-1,"region":"iad1","maxMemoryUsed":-1,"memorySize":-1,"message":"trap_external>\", line 999, in exec_module\nFile \"<frozen importlib._bootstrap>\", line 488, in _call_with_frames_removed\nFile \"/var/task/api/index.py\", line 24, in <module>\nfrom github_api_scraper import Base, MarkerHit\nFile \"/var/task/github_api_scraper.py\", line 72, in <module>\nBase.metadata.create_all(bind=engine)\nFile \"/var/task/sqlalchemy/sql/schema.py\", line 5924, in create_all\nbind._run_ddl_visitor(\nFile \"/var/task/sqlalchemy/engine/base.py\", line 3245, in _run_ddl_visitor\nwith self.begin() as conn:\n^^^^^^^^^^^^\nFile \"/var/lang/lib/python3.12/contextlib.py\", line 137, in __enter__\nreturn next(self.gen)\n^^^^^^^^^^^^^^\nFile \"/var/task/sqlalchemy/engine/base.py\", line 3235, in begin\nwith self.connect() as conn:\n^^^^^^^^^^^^^^\nFile \"/var/task/sqlalchemy/engine/base.py\", line 3271, in connect\nreturn self._connection_cls(self)\n^^^^^^^^^^^^^^^^^^^^^^^^^^\nFile \"/var/task/sqlalchemy/engine/base.py\", line 145, in __init__\nConnection._handle_dbapi_exception_noconnection(\nFile \"/var/task/sqlalchemy/engine/base.py\", line 2434, in _handle_dbapi_exception_noconnection\nraise sqlalchemy_exception.with_traceback(exc_info[2]) from e\nFile \"/var/task/sqlalchemy/engine/base.py\", line 143, in __init__\nself._dbapi_connection = engine.raw_connection()\n^^^^^^^^^^^^^^^^^^^^^^^\nFile \"/var/task/sqlalchemy/engine/base.py\", line 3295, in raw_connection\nreturn self.pool.connect()\n^^^^^^^^^^^^^^^^^^^\nFile \"/var/task/sqlalchemy/pool/base.py\", line 447, in connect\nreturn _ConnectionFairy._checkout(self)\n^^^^^^^^^^^^^^^^^^^^^^^^^^^^^^^^\nFile \"/var/task/sqlalchemy/pool/base.py\", line 1264, in _checkout\nfairy = _ConnectionRecord.checkout(pool)\n^^^^^^^^^^^^^^^^^^^^^^^^^^^^^^^^\nFile \"/var/task/sqlalchemy/pool/base.py\", line 711, in checkout\nrec = pool._do_get()\n^^^^^^^^^^^^^^\nFile \"/var/task/sqlalchemy/pool/impl.py\", line 177, in _do_get\nwith util.safe_reraise():\n^^^^^^^^^^^^^^^^^^^\nFile \"/var/task/sqlalchemy/util/langhelpers.py\", line 224, in __exit__\nraise exc_value.with_traceback(exc_tb)\nFile \"/var/task/sqlalchemy/pool/impl.py\", line 175, in _do_get\nreturn self._create_connection()\n^^^^^^^^^^^^^^^^^^^^^^^^^\nFile \"/var/task/sqlalchemy/pool/base.py\", line 388, in _create_connection\nreturn _ConnectionRecord(self)\n^^^^^^^^^^^^^^^^^^^^^^^\nFile \"/var/task/sqlalchemy/pool/base.py\", line 673, in __init__\nself.__connect()\nFile \"/var/task/sqlalchemy/pool/base.py\", line 899, in __connect\nwith util.safe_reraise():\n^^^^^^^^^^^^^^^^^^^\nFile \"/var/task/sqlalchemy/util/langhelpers.py\", line 224, in __exit__\nraise exc_value.with_traceback(exc_tb)\nFile \"/var/task/sqlalchemy/pool/base.py\", line 895, in __connect\nself.dbapi_connection = connection = pool._invoke_creator(self)\n^^^^^^^^^^^^^^^^^^^^^^^^^^\nFile \"/var/task/sqlalchemy/engine/create.py\", line 646, in connect\nreturn dialect.connect(*cargs, **cparams)\n^^^^^^^^^^^^^^^^^^^^^^^^^^^^^^^^^^\nFile \"/var/task/sqlalchemy/engine/default.py\", line 626, in connect\nreturn self.loaded_dbapi.connect(*cargs, **cparams)  # type: ignore[no-any-return]  # NOQA: E501\n^^^^^^^^^^^^^^^^^^^^^^^^^^^^^^^^^^^^^^^^^^^^\nFile \"/var/task/psycopg2/__init__.py\", line 122, in connect\nconn = _connect(dsn, connection_factory=connection_factory, **kwasync)\n^^^^^^^^^^^^^^^^^^^^^^^^^^^^^^^^^^^^^^^^^^^^^^^^^^^^^^^^^^^^^^^\nsqlalchemy.exc.OperationalError: (psycopg2.OperationalError) connection to server at \"db.ymmyielhidafnqvbsdra.supabase.co\" (2600:1f18:2e13:9d11:9819:684:a689:9dd9), port 5432 failed: Cannot assign requested address\nIs the server running on that host and accepting TCP/IP connections?\n(Background on this error at: https://sqlalche.me/e/20/e3q8)\nPython process exited with exit status: 1. The logs above can help with debugging the issue.","projectId":"prj_tQqdVztKk9tpelT7m49G7XNyEFrV","traceId":"","sessionId":"","invocationId":"01K21KNPE2ZTRJGXM13VDBN4VG","instanceId":"","concurrency":-1},{"TimeUTC":"2025-08-07 06:32:20","timestampInMs":1754548340928,"requestPath":"ai-checker-oy8mnk3j4-chris-anzilottis-projects.vercel.app/","requestMethod":"GET","requestQueryString":"","responseStatusCode":-1,"requestId":"5cdhg-1754548328446-f7fbb63f5d60","requestUserAgent":"vercel-screenshot/1.0","level":"error","environment":"production","branch":"master","vercelCache":"MISS","type":"lambda","function":"/api/index","host":"ai-checker-oy8mnk3j4-chris-anzilottis-projects.vercel.app","deploymentDomain":"ai-checker-oy8mnk3j4-chris-anzilottis-projects.vercel.app","deploymentId":"dpl_CevT8h1YNj63hdtAytibbLR52ZrV","durationMs":-1,"region":"iad1","maxMemoryUsed":-1,"memorySize":-1,"message":"trap_external>\", line 999, in exec_module\nFile \"<frozen importlib._bootstrap>\", line 488, in _call_with_frames_removed\nFile \"/var/task/api/index.py\", line 24, in <module>\nfrom github_api_scraper import Base, MarkerHit\nFile \"/var/task/github_api_scraper.py\", line 72, in <module>\nBase.metadata.create_all(bind=engine)\nFile \"/var/task/sqlalchemy/sql/schema.py\", line 5924, in create_all\nbind._run_ddl_visitor(\nFile \"/var/task/sqlalchemy/engine/base.py\", line 3245, in _run_ddl_visitor\nwith self.begin() as conn:\n^^^^^^^^^^^^\nFile \"/var/lang/lib/python3.12/contextlib.py\", line 137, in __enter__\nreturn next(self.gen)\n^^^^^^^^^^^^^^\nFile \"/var/task/sqlalchemy/engine/base.py\", line 3235, in begin\nwith self.connect() as conn:\n^^^^^^^^^^^^^^\nFile \"/var/task/sqlalchemy/engine/base.py\", line 3271, in connect\nreturn self._connection_cls(self)\n^^^^^^^^^^^^^^^^^^^^^^^^^^\nFile \"/var/task/sqlalchemy/engine/base.py\", line 145, in __init__\nConnection._handle_dbapi_exception_noconnection(\nFile \"/var/task/sqlalchemy/engine/base.py\", line 2434, in _handle_dbapi_exception_noconnection\nraise sqlalchemy_exception.with_traceback(exc_info[2]) from e\nFile \"/var/task/sqlalchemy/engine/base.py\", line 143, in __init__\nself._dbapi_connection = engine.raw_connection()\n^^^^^^^^^^^^^^^^^^^^^^^\nFile \"/var/task/sqlalchemy/engine/base.py\", line 3295, in raw_connection\nreturn self.pool.connect()\n^^^^^^^^^^^^^^^^^^^\nFile \"/var/task/sqlalchemy/pool/base.py\", line 447, in connect\nreturn _ConnectionFairy._checkout(self)\n^^^^^^^^^^^^^^^^^^^^^^^^^^^^^^^^\nFile \"/var/task/sqlalchemy/pool/base.py\", line 1264, in _checkout\nfairy = _ConnectionRecord.checkout(pool)\n^^^^^^^^^^^^^^^^^^^^^^^^^^^^^^^^\nFile \"/var/task/sqlalchemy/pool/base.py\", line 711, in checkout\nrec = pool._do_get()\n^^^^^^^^^^^^^^\nFile \"/var/task/sqlalchemy/pool/impl.py\", line 177, in _do_get\nwith util.safe_reraise():\n^^^^^^^^^^^^^^^^^^^\nFile \"/var/task/sqlalchemy/util/langhelpers.py\", line 224, in __exit__\nraise exc_value.with_traceback(exc_tb)\nFile \"/var/task/sqlalchemy/pool/impl.py\", line 175, in _do_get\nreturn self._create_connection()\n^^^^^^^^^^^^^^^^^^^^^^^^^\nFile \"/var/task/sqlalchemy/pool/base.py\", line 388, in _create_connection\nreturn _ConnectionRecord(self)\n^^^^^^^^^^^^^^^^^^^^^^^\nFile \"/var/task/sqlalchemy/pool/base.py\", line 673, in __init__\nself.__connect()\nFile \"/var/task/sqlalchemy/pool/base.py\", line 899, in __connect\nwith util.safe_reraise():\n^^^^^^^^^^^^^^^^^^^\nFile \"/var/task/sqlalchemy/util/langhelpers.py\", line 224, in __exit__\nraise exc_value.with_traceback(exc_tb)\nFile \"/var/task/sqlalchemy/pool/base.py\", line 895, in __connect\nself.dbapi_connection = connection = pool._invoke_creator(self)\n^^^^^^^^^^^^^^^^^^^^^^^^^^\nFile \"/var/task/sqlalchemy/engine/create.py\", line 646, in connect\nreturn dialect.connect(*cargs, **cparams)\n^^^^^^^^^^^^^^^^^^^^^^^^^^^^^^^^^^\nFile \"/var/task/sqlalchemy/engine/default.py\", line 626, in connect\nreturn self.loaded_dbapi.connect(*cargs, **cparams)  # type: ignore[no-any-return]  # NOQA: E501\n^^^^^^^^^^^^^^^^^^^^^^^^^^^^^^^^^^^^^^^^^^^^\nFile \"/var/task/psycopg2/__init__.py\", line 122, in connect\nconn = _connect(dsn, connection_factory=connection_factory, **kwasync)\n^^^^^^^^^^^^^^^^^^^^^^^^^^^^^^^^^^^^^^^^^^^^^^^^^^^^^^^^^^^^^^^\nsqlalchemy.exc.OperationalError: (psycopg2.OperationalError) connection to server at \"db.ymmyielhidafnqvbsdra.supabase.co\" (2600:1f18:2e13:9d11:9819:684:a689:9dd9), port 5432 failed: Cannot assign requested address\nIs the server running on that host and accepting TCP/IP connections?\n(Background on this error at: https://sqlalche.me/e/20/e3q8)\nPython process exited with exit status: 1. The logs above can help with debugging the issue.","projectId":"prj_tQqdVztKk9tpelT7m49G7XNyEFrV","traceId":"","sessionId":"","invocationId":"01K21KNP18WMJCCPHPKW7DGCT1","instanceId":"","concurrency":-1},{"TimeUTC":"2025-08-07 06:32:20","timestampInMs":1754548340501,"requestPath":"ai-checker-oy8mnk3j4-chris-anzilottis-projects.vercel.app/favicon.ico","requestMethod":"GET","requestQueryString":"","responseStatusCode":500,"requestId":"lkrrf-1754548340456-1bb1a8aeb63f","requestUserAgent":"vercel-favicon/1.0","level":"error","environment":"production","branch":"master","vercelCache":"MISS","type":"lambda","function":"/api/index","host":"ai-checker-oy8mnk3j4-chris-anzilottis-projects.vercel.app","deploymentDomain":"ai-checker-oy8mnk3j4-chris-anzilottis-projects.vercel.app","deploymentId":"dpl_CevT8h1YNj63hdtAytibbLR52ZrV","durationMs":5000,"region":"iad1","maxMemoryUsed":239,"memorySize":2048,"message":"","projectId":"prj_tQqdVztKk9tpelT7m49G7XNyEFrV","traceId":"","sessionId":"","invocationId":"01K21KP1RN0361FTBKV99XBCFP","instanceId":"","concurrency":1},{"TimeUTC":"2025-08-07 06:32:19","timestampInMs":1754548339284,"requestPath":"ai-checker-oy8mnk3j4-chris-anzilottis-projects.vercel.app/","requestMethod":"GET","requestQueryString":"","responseStatusCode":-1,"requestId":"mcp6l-1754548328350-641438ebbaa1","requestUserAgent":"vercel-favicon/1.0","level":"error","environment":"production","branch":"master","vercelCache":"MISS","type":"lambda","function":"/api/index","host":"ai-checker-oy8mnk3j4-chris-anzilottis-projects.vercel.app","deploymentDomain":"ai-checker-oy8mnk3j4-chris-anzilottis-projects.vercel.app","deploymentId":"dpl_CevT8h1YNj63hdtAytibbLR52ZrV","durationMs":-1,"region":"iad1","maxMemoryUsed":-1,"memorySize":-1,"message":"trap_external>\", line 999, in exec_module\nFile \"<frozen importlib._bootstrap>\", line 488, in _call_with_frames_removed\nFile \"/var/task/api/index.py\", line 24, in <module>\nfrom github_api_scraper import Base, MarkerHit\nFile \"/var/task/github_api_scraper.py\", line 72, in <module>\nBase.metadata.create_all(bind=engine)\nFile \"/var/task/sqlalchemy/sql/schema.py\", line 5924, in create_all\nbind._run_ddl_visitor(\nFile \"/var/task/sqlalchemy/engine/base.py\", line 3245, in _run_ddl_visitor\nwith self.begin() as conn:\n^^^^^^^^^^^^\nFile \"/var/lang/lib/python3.12/contextlib.py\", line 137, in __enter__\nreturn next(self.gen)\n^^^^^^^^^^^^^^\nFile \"/var/task/sqlalchemy/engine/base.py\", line 3235, in begin\nwith self.connect() as conn:\n^^^^^^^^^^^^^^\nFile \"/var/task/sqlalchemy/engine/base.py\", line 3271, in connect\nreturn self._connection_cls(self)\n^^^^^^^^^^^^^^^^^^^^^^^^^^\nFile \"/var/task/sqlalchemy/engine/base.py\", line 145, in __init__\nConnection._handle_dbapi_exception_noconnection(\nFile \"/var/task/sqlalchemy/engine/base.py\", line 2434, in _handle_dbapi_exception_noconnection\nraise sqlalchemy_exception.with_traceback(exc_info[2]) from e\nFile \"/var/task/sqlalchemy/engine/base.py\", line 143, in __init__\nself._dbapi_connection = engine.raw_connection()\n^^^^^^^^^^^^^^^^^^^^^^^\nFile \"/var/task/sqlalchemy/engine/base.py\", line 3295, in raw_connection\nreturn self.pool.connect()\n^^^^^^^^^^^^^^^^^^^\nFile \"/var/task/sqlalchemy/pool/base.py\", line 447, in connect\nreturn _ConnectionFairy._checkout(self)\n^^^^^^^^^^^^^^^^^^^^^^^^^^^^^^^^\nFile \"/var/task/sqlalchemy/pool/base.py\", line 1264, in _checkout\nfairy = _ConnectionRecord.checkout(pool)\n^^^^^^^^^^^^^^^^^^^^^^^^^^^^^^^^\nFile \"/var/task/sqlalchemy/pool/base.py\", line 711, in checkout\nrec = pool._do_get()\n^^^^^^^^^^^^^^\nFile \"/var/task/sqlalchemy/pool/impl.py\", line 177, in _do_get\nwith util.safe_reraise():\n^^^^^^^^^^^^^^^^^^^\nFile \"/var/task/sqlalchemy/util/langhelpers.py\", line 224, in __exit__\nraise exc_value.with_traceback(exc_tb)\nFile \"/var/task/sqlalchemy/pool/impl.py\", line 175, in _do_get\nreturn self._create_connection()\n^^^^^^^^^^^^^^^^^^^^^^^^^\nFile \"/var/task/sqlalchemy/pool/base.py\", line 388, in _create_connection\nreturn _ConnectionRecord(self)\n^^^^^^^^^^^^^^^^^^^^^^^\nFile \"/var/task/sqlalchemy/pool/base.py\", line 673, in __init__\nself.__connect()\nFile \"/var/task/sqlalchemy/pool/base.py\", line 899, in __connect\nwith util.safe_reraise():\n^^^^^^^^^^^^^^^^^^^\nFile \"/var/task/sqlalchemy/util/langhelpers.py\", line 224, in __exit__\nraise exc_value.with_traceback(exc_tb)\nFile \"/var/task/sqlalchemy/pool/base.py\", line 895, in __connect\nself.dbapi_connection = connection = pool._invoke_creator(self)\n^^^^^^^^^^^^^^^^^^^^^^^^^^\nFile \"/var/task/sqlalchemy/engine/create.py\", line 646, in connect\nreturn dialect.connect(*cargs, **cparams)\n^^^^^^^^^^^^^^^^^^^^^^^^^^^^^^^^^^\nFile \"/var/task/sqlalchemy/engine/default.py\", line 626, in connect\nreturn self.loaded_dbapi.connect(*cargs, **cparams)  # type: ignore[no-any-return]  # NOQA: E501\n^^^^^^^^^^^^^^^^^^^^^^^^^^^^^^^^^^^^^^^^^^^^\nFile \"/var/task/psycopg2/__init__.py\", line 122, in connect\nconn = _connect(dsn, connection_factory=connection_factory, **kwasync)\n^^^^^^^^^^^^^^^^^^^^^^^^^^^^^^^^^^^^^^^^^^^^^^^^^^^^^^^^^^^^^^^\nsqlalchemy.exc.OperationalError: (psycopg2.OperationalError) connection to server at \"db.ymmyielhidafnqvbsdra.supabase.co\" (2600:1f18:2e13:9d11:9819:684:a689:9dd9), port 5432 failed: Cannot assign requested address\nIs the server running on that host and accepting TCP/IP connections?\n(Background on this error at: https://sqlalche.me/e/20/e3q8)\nPython process exited with exit status: 1. The logs above can help with debugging the issue.","projectId":"prj_tQqdVztKk9tpelT7m49G7XNyEFrV","traceId":"","sessionId":"","invocationId":"01K21KNNY6HD01T4RMZQC3Q1JA","instanceId":"","concurrency":-1},{"TimeUTC":"2025-08-07 06:32:18","timestampInMs":1754548338413,"requestPath":"ai-checker-oy8mnk3j4-chris-anzilottis-projects.vercel.app/","requestMethod":"GET","requestQueryString":"","responseStatusCode":-1,"requestId":"xtqxh-1754548324384-5788700dd3cb","requestUserAgent":"vercel-screenshot/1.0","level":"error","environment":"production","branch":"master","vercelCache":"MISS","type":"lambda","function":"/api/index","host":"ai-checker-oy8mnk3j4-chris-anzilottis-projects.vercel.app","deploymentDomain":"ai-checker-oy8mnk3j4-chris-anzilottis-projects.vercel.app","deploymentId":"dpl_CevT8h1YNj63hdtAytibbLR52ZrV","durationMs":-1,"region":"iad1","maxMemoryUsed":-1,"memorySize":-1,"message":"trap_external>\", line 999, in exec_module\nFile \"<frozen importlib._bootstrap>\", line 488, in _call_with_frames_removed\nFile \"/var/task/api/index.py\", line 24, in <module>\nfrom github_api_scraper import Base, MarkerHit\nFile \"/var/task/github_api_scraper.py\", line 72, in <module>\nBase.metadata.create_all(bind=engine)\nFile \"/var/task/sqlalchemy/sql/schema.py\", line 5924, in create_all\nbind._run_ddl_visitor(\nFile \"/var/task/sqlalchemy/engine/base.py\", line 3245, in _run_ddl_visitor\nwith self.begin() as conn:\n^^^^^^^^^^^^\nFile \"/var/lang/lib/python3.12/contextlib.py\", line 137, in __enter__\nreturn next(self.gen)\n^^^^^^^^^^^^^^\nFile \"/var/task/sqlalchemy/engine/base.py\", line 3235, in begin\nwith self.connect() as conn:\n^^^^^^^^^^^^^^\nFile \"/var/task/sqlalchemy/engine/base.py\", line 3271, in connect\nreturn self._connection_cls(self)\n^^^^^^^^^^^^^^^^^^^^^^^^^^\nFile \"/var/task/sqlalchemy/engine/base.py\", line 145, in __init__\nConnection._handle_dbapi_exception_noconnection(\nFile \"/var/task/sqlalchemy/engine/base.py\", line 2434, in _handle_dbapi_exception_noconnection\nraise sqlalchemy_exception.with_traceback(exc_info[2]) from e\nFile \"/var/task/sqlalchemy/engine/base.py\", line 143, in __init__\nself._dbapi_connection = engine.raw_connection()\n^^^^^^^^^^^^^^^^^^^^^^^\nFile \"/var/task/sqlalchemy/engine/base.py\", line 3295, in raw_connection\nreturn self.pool.connect()\n^^^^^^^^^^^^^^^^^^^\nFile \"/var/task/sqlalchemy/pool/base.py\", line 447, in connect\nreturn _ConnectionFairy._checkout(self)\n^^^^^^^^^^^^^^^^^^^^^^^^^^^^^^^^\nFile \"/var/task/sqlalchemy/pool/base.py\", line 1264, in _checkout\nfairy = _ConnectionRecord.checkout(pool)\n^^^^^^^^^^^^^^^^^^^^^^^^^^^^^^^^\nFile \"/var/task/sqlalchemy/pool/base.py\", line 711, in checkout\nrec = pool._do_get()\n^^^^^^^^^^^^^^\nFile \"/var/task/sqlalchemy/pool/impl.py\", line 177, in _do_get\nwith util.safe_reraise():\n^^^^^^^^^^^^^^^^^^^\nFile \"/var/task/sqlalchemy/util/langhelpers.py\", line 224, in __exit__\nraise exc_value.with_traceback(exc_tb)\nFile \"/var/task/sqlalchemy/pool/impl.py\", line 175, in _do_get\nreturn self._create_connection()\n^^^^^^^^^^^^^^^^^^^^^^^^^\nFile \"/var/task/sqlalchemy/pool/base.py\", line 388, in _create_connection\nreturn _ConnectionRecord(self)\n^^^^^^^^^^^^^^^^^^^^^^^\nFile \"/var/task/sqlalchemy/pool/base.py\", line 673, in __init__\nself.__connect()\nFile \"/var/task/sqlalchemy/pool/base.py\", line 899, in __connect\nwith util.safe_reraise():\n^^^^^^^^^^^^^^^^^^^\nFile \"/var/task/sqlalchemy/util/langhelpers.py\", line 224, in __exit__\nraise exc_value.with_traceback(exc_tb)\nFile \"/var/task/sqlalchemy/pool/base.py\", line 895, in __connect\nself.dbapi_connection = connection = pool._invoke_creator(self)\n^^^^^^^^^^^^^^^^^^^^^^^^^^\nFile \"/var/task/sqlalchemy/engine/create.py\", line 646, in connect\nreturn dialect.connect(*cargs, **cparams)\n^^^^^^^^^^^^^^^^^^^^^^^^^^^^^^^^^^\nFile \"/var/task/sqlalchemy/engine/default.py\", line 626, in connect\nreturn self.loaded_dbapi.connect(*cargs, **cparams)  # type: ignore[no-any-return]  # NOQA: E501\n^^^^^^^^^^^^^^^^^^^^^^^^^^^^^^^^^^^^^^^^^^^^\nFile \"/var/task/psycopg2/__init__.py\", line 122, in connect\nconn = _connect(dsn, connection_factory=connection_factory, **kwasync)\n^^^^^^^^^^^^^^^^^^^^^^^^^^^^^^^^^^^^^^^^^^^^^^^^^^^^^^^^^^^^^^^\nsqlalchemy.exc.OperationalError: (psycopg2.OperationalError) connection to server at \"db.ymmyielhidafnqvbsdra.supabase.co\" (2600:1f18:2e13:9d11:9819:684:a689:9dd9), port 5432 failed: Cannot assign requested address\nIs the server running on that host and accepting TCP/IP connections?\n(Background on this error at: https://sqlalche.me/e/20/e3q8)\nPython process exited with exit status: 1. The logs above can help with debugging the issue.","projectId":"prj_tQqdVztKk9tpelT7m49G7XNyEFrV","traceId":"","sessionId":"","invocationId":"01K21KNJ9JJ3SEX1F0AR536VY3","instanceId":"","concurrency":-1},{"TimeUTC":"2025-08-07 06:32:17","timestampInMs":1754548337405,"requestPath":"ai-checker-oy8mnk3j4-chris-anzilottis-projects.vercel.app/","requestMethod":"GET","requestQueryString":"","responseStatusCode":-1,"requestId":"qrhjr-1754548324402-b846e44d78a3","requestUserAgent":"vercel-screenshot/1.0","level":"error","environment":"production","branch":"master","vercelCache":"MISS","type":"lambda","function":"/api/index","host":"ai-checker-oy8mnk3j4-chris-anzilottis-projects.vercel.app","deploymentDomain":"ai-checker-oy8mnk3j4-chris-anzilottis-projects.vercel.app","deploymentId":"dpl_CevT8h1YNj63hdtAytibbLR52ZrV","durationMs":-1,"region":"iad1","maxMemoryUsed":-1,"memorySize":-1,"message":"trap_external>\", line 999, in exec_module\nFile \"<frozen importlib._bootstrap>\", line 488, in _call_with_frames_removed\nFile \"/var/task/api/index.py\", line 24, in <module>\nfrom github_api_scraper import Base, MarkerHit\nFile \"/var/task/github_api_scraper.py\", line 72, in <module>\nBase.metadata.create_all(bind=engine)\nFile \"/var/task/sqlalchemy/sql/schema.py\", line 5924, in create_all\nbind._run_ddl_visitor(\nFile \"/var/task/sqlalchemy/engine/base.py\", line 3245, in _run_ddl_visitor\nwith self.begin() as conn:\n^^^^^^^^^^^^\nFile \"/var/lang/lib/python3.12/contextlib.py\", line 137, in __enter__\nreturn next(self.gen)\n^^^^^^^^^^^^^^\nFile \"/var/task/sqlalchemy/engine/base.py\", line 3235, in begin\nwith self.connect() as conn:\n^^^^^^^^^^^^^^\nFile \"/var/task/sqlalchemy/engine/base.py\", line 3271, in connect\nreturn self._connection_cls(self)\n^^^^^^^^^^^^^^^^^^^^^^^^^^\nFile \"/var/task/sqlalchemy/engine/base.py\", line 145, in __init__\nConnection._handle_dbapi_exception_noconnection(\nFile \"/var/task/sqlalchemy/engine/base.py\", line 2434, in _handle_dbapi_exception_noconnection\nraise sqlalchemy_exception.with_traceback(exc_info[2]) from e\nFile \"/var/task/sqlalchemy/engine/base.py\", line 143, in __init__\nself._dbapi_connection = engine.raw_connection()\n^^^^^^^^^^^^^^^^^^^^^^^\nFile \"/var/task/sqlalchemy/engine/base.py\", line 3295, in raw_connection\nreturn self.pool.connect()\n^^^^^^^^^^^^^^^^^^^\nFile \"/var/task/sqlalchemy/pool/base.py\", line 447, in connect\nreturn _ConnectionFairy._checkout(self)\n^^^^^^^^^^^^^^^^^^^^^^^^^^^^^^^^\nFile \"/var/task/sqlalchemy/pool/base.py\", line 1264, in _checkout\nfairy = _ConnectionRecord.checkout(pool)\n^^^^^^^^^^^^^^^^^^^^^^^^^^^^^^^^\nFile \"/var/task/sqlalchemy/pool/base.py\", line 711, in checkout\nrec = pool._do_get()\n^^^^^^^^^^^^^^\nFile \"/var/task/sqlalchemy/pool/impl.py\", line 177, in _do_get\nwith util.safe_reraise():\n^^^^^^^^^^^^^^^^^^^\nFile \"/var/task/sqlalchemy/util/langhelpers.py\", line 224, in __exit__\nraise exc_value.with_traceback(exc_tb)\nFile \"/var/task/sqlalchemy/pool/impl.py\", line 175, in _do_get\nreturn self._create_connection()\n^^^^^^^^^^^^^^^^^^^^^^^^^\nFile \"/var/task/sqlalchemy/pool/base.py\", line 388, in _create_connection\nreturn _ConnectionRecord(self)\n^^^^^^^^^^^^^^^^^^^^^^^\nFile \"/var/task/sqlalchemy/pool/base.py\", line 673, in __init__\nself.__connect()\nFile \"/var/task/sqlalchemy/pool/base.py\", line 899, in __connect\nwith util.safe_reraise():\n^^^^^^^^^^^^^^^^^^^\nFile \"/var/task/sqlalchemy/util/langhelpers.py\", line 224, in __exit__\nraise exc_value.with_traceback(exc_tb)\nFile \"/var/task/sqlalchemy/pool/base.py\", line 895, in __connect\nself.dbapi_connection = connection = pool._invoke_creator(self)\n^^^^^^^^^^^^^^^^^^^^^^^^^^\nFile \"/var/task/sqlalchemy/engine/create.py\", line 646, in connect\nreturn dialect.connect(*cargs, **cparams)\n^^^^^^^^^^^^^^^^^^^^^^^^^^^^^^^^^^\nFile \"/var/task/sqlalchemy/engine/default.py\", line 626, in connect\nreturn self.loaded_dbapi.connect(*cargs, **cparams)  # type: ignore[no-any-return]  # NOQA: E501\n^^^^^^^^^^^^^^^^^^^^^^^^^^^^^^^^^^^^^^^^^^^^\nFile \"/var/task/psycopg2/__init__.py\", line 122, in connect\nconn = _connect(dsn, connection_factory=connection_factory, **kwasync)\n^^^^^^^^^^^^^^^^^^^^^^^^^^^^^^^^^^^^^^^^^^^^^^^^^^^^^^^^^^^^^^^\nsqlalchemy.exc.OperationalError: (psycopg2.OperationalError) connection to server at \"db.ymmyielhidafnqvbsdra.supabase.co\" (2600:1f18:2e13:9d11:9819:684:a689:9dd9), port 5432 failed: Cannot assign requested address\nIs the server running on that host and accepting TCP/IP connections?\n(Background on this error at: https://sqlalche.me/e/20/e3q8)\nPython process exited with exit status: 1. The logs above can help with debugging the issue.","projectId":"prj_tQqdVztKk9tpelT7m49G7XNyEFrV","traceId":"","sessionId":"","invocationId":"01K21KNJ9HA60813MDBHS4GG54","instanceId":"","concurrency":-1},{"TimeUTC":"2025-08-07 06:32:17","timestampInMs":1754548337379,"requestPath":"ai-checker-oy8mnk3j4-chris-anzilottis-projects.vercel.app/","requestMethod":"GET","requestQueryString":"","responseStatusCode":-1,"requestId":"k5xm9-1754548324407-8fb55c5392c7","requestUserAgent":"vercel-favicon/1.0","level":"error","environment":"production","branch":"master","vercelCache":"MISS","type":"lambda","function":"/api/index","host":"ai-checker-oy8mnk3j4-chris-anzilottis-projects.vercel.app","deploymentDomain":"ai-checker-oy8mnk3j4-chris-anzilottis-projects.vercel.app","deploymentId":"dpl_CevT8h1YNj63hdtAytibbLR52ZrV","durationMs":-1,"region":"iad1","maxMemoryUsed":-1,"memorySize":-1,"message":"trap_external>\", line 999, in exec_module\nFile \"<frozen importlib._bootstrap>\", line 488, in _call_with_frames_removed\nFile \"/var/task/api/index.py\", line 24, in <module>\nfrom github_api_scraper import Base, MarkerHit\nFile \"/var/task/github_api_scraper.py\", line 72, in <module>\nBase.metadata.create_all(bind=engine)\nFile \"/var/task/sqlalchemy/sql/schema.py\", line 5924, in create_all\nbind._run_ddl_visitor(\nFile \"/var/task/sqlalchemy/engine/base.py\", line 3245, in _run_ddl_visitor\nwith self.begin() as conn:\n^^^^^^^^^^^^\nFile \"/var/lang/lib/python3.12/contextlib.py\", line 137, in __enter__\nreturn next(self.gen)\n^^^^^^^^^^^^^^\nFile \"/var/task/sqlalchemy/engine/base.py\", line 3235, in begin\nwith self.connect() as conn:\n^^^^^^^^^^^^^^\nFile \"/var/task/sqlalchemy/engine/base.py\", line 3271, in connect\nreturn self._connection_cls(self)\n^^^^^^^^^^^^^^^^^^^^^^^^^^\nFile \"/var/task/sqlalchemy/engine/base.py\", line 145, in __init__\nConnection._handle_dbapi_exception_noconnection(\nFile \"/var/task/sqlalchemy/engine/base.py\", line 2434, in _handle_dbapi_exception_noconnection\nraise sqlalchemy_exception.with_traceback(exc_info[2]) from e\nFile \"/var/task/sqlalchemy/engine/base.py\", line 143, in __init__\nself._dbapi_connection = engine.raw_connection()\n^^^^^^^^^^^^^^^^^^^^^^^\nFile \"/var/task/sqlalchemy/engine/base.py\", line 3295, in raw_connection\nreturn self.pool.connect()\n^^^^^^^^^^^^^^^^^^^\nFile \"/var/task/sqlalchemy/pool/base.py\", line 447, in connect\nreturn _ConnectionFairy._checkout(self)\n^^^^^^^^^^^^^^^^^^^^^^^^^^^^^^^^\nFile \"/var/task/sqlalchemy/pool/base.py\", line 1264, in _checkout\nfairy = _ConnectionRecord.checkout(pool)\n^^^^^^^^^^^^^^^^^^^^^^^^^^^^^^^^\nFile \"/var/task/sqlalchemy/pool/base.py\", line 711, in checkout\nrec = pool._do_get()\n^^^^^^^^^^^^^^\nFile \"/var/task/sqlalchemy/pool/impl.py\", line 177, in _do_get\nwith util.safe_reraise():\n^^^^^^^^^^^^^^^^^^^\nFile \"/var/task/sqlalchemy/util/langhelpers.py\", line 224, in __exit__\nraise exc_value.with_traceback(exc_tb)\nFile \"/var/task/sqlalchemy/pool/impl.py\", line 175, in _do_get\nreturn self._create_connection()\n^^^^^^^^^^^^^^^^^^^^^^^^^\nFile \"/var/task/sqlalchemy/pool/base.py\", line 388, in _create_connection\nreturn _ConnectionRecord(self)\n^^^^^^^^^^^^^^^^^^^^^^^\nFile \"/var/task/sqlalchemy/pool/base.py\", line 673, in __init__\nself.__connect()\nFile \"/var/task/sqlalchemy/pool/base.py\", line 899, in __connect\nwith util.safe_reraise():\n^^^^^^^^^^^^^^^^^^^\nFile \"/var/task/sqlalchemy/util/langhelpers.py\", line 224, in __exit__\nraise exc_value.with_traceback(exc_tb)\nFile \"/var/task/sqlalchemy/pool/base.py\", line 895, in __connect\nself.dbapi_connection = connection = pool._invoke_creator(self)\n^^^^^^^^^^^^^^^^^^^^^^^^^^\nFile \"/var/task/sqlalchemy/engine/create.py\", line 646, in connect\nreturn dialect.connect(*cargs, **cparams)\n^^^^^^^^^^^^^^^^^^^^^^^^^^^^^^^^^^\nFile \"/var/task/sqlalchemy/engine/default.py\", line 626, in connect\nreturn self.loaded_dbapi.connect(*cargs, **cparams)  # type: ignore[no-any-return]  # NOQA: E501\n^^^^^^^^^^^^^^^^^^^^^^^^^^^^^^^^^^^^^^^^^^^^\nFile \"/var/task/psycopg2/__init__.py\", line 122, in connect\nconn = _connect(dsn, connection_factory=connection_factory, **kwasync)\n^^^^^^^^^^^^^^^^^^^^^^^^^^^^^^^^^^^^^^^^^^^^^^^^^^^^^^^^^^^^^^^\nsqlalchemy.exc.OperationalError: (psycopg2.OperationalError) connection to server at \"db.ymmyielhidafnqvbsdra.supabase.co\" (2600:1f18:2e13:9d11:9819:684:a689:9dd9), port 5432 failed: Cannot assign requested address\nIs the server running on that host and accepting TCP/IP connections?\n(Background on this error at: https://sqlalche.me/e/20/e3q8)\nPython process exited with exit status: 1. The logs above can help with debugging the issue.","projectId":"prj_tQqdVztKk9tpelT7m49G7XNyEFrV","traceId":"","sessionId":"","invocationId":"01K21KNJ9HA60813MDBFP9MBTA","instanceId":"","concurrency":-1},{"TimeUTC":"2025-08-07 06:32:17","timestampInMs":1754548337195,"requestPath":"ai-checker-oy8mnk3j4-chris-anzilottis-projects.vercel.app/","requestMethod":"GET","requestQueryString":"","responseStatusCode":-1,"requestId":"wwgjx-1754548324479-f25676d21443","requestUserAgent":"vercel-favicon/1.0","level":"error","environment":"production","branch":"master","vercelCache":"MISS","type":"lambda","function":"/api/index","host":"ai-checker-oy8mnk3j4-chris-anzilottis-projects.vercel.app","deploymentDomain":"ai-checker-oy8mnk3j4-chris-anzilottis-projects.vercel.app","deploymentId":"dpl_CevT8h1YNj63hdtAytibbLR52ZrV","durationMs":-1,"region":"iad1","maxMemoryUsed":-1,"memorySize":-1,"message":"trap_external>\", line 999, in exec_module\nFile \"<frozen importlib._bootstrap>\", line 488, in _call_with_frames_removed\nFile \"/var/task/api/index.py\", line 24, in <module>\nfrom github_api_scraper import Base, MarkerHit\nFile \"/var/task/github_api_scraper.py\", line 72, in <module>\nBase.metadata.create_all(bind=engine)\nFile \"/var/task/sqlalchemy/sql/schema.py\", line 5924, in create_all\nbind._run_ddl_visitor(\nFile \"/var/task/sqlalchemy/engine/base.py\", line 3245, in _run_ddl_visitor\nwith self.begin() as conn:\n^^^^^^^^^^^^\nFile \"/var/lang/lib/python3.12/contextlib.py\", line 137, in __enter__\nreturn next(self.gen)\n^^^^^^^^^^^^^^\nFile \"/var/task/sqlalchemy/engine/base.py\", line 3235, in begin\nwith self.connect() as conn:\n^^^^^^^^^^^^^^\nFile \"/var/task/sqlalchemy/engine/base.py\", line 3271, in connect\nreturn self._connection_cls(self)\n^^^^^^^^^^^^^^^^^^^^^^^^^^\nFile \"/var/task/sqlalchemy/engine/base.py\", line 145, in __init__\nConnection._handle_dbapi_exception_noconnection(\nFile \"/var/task/sqlalchemy/engine/base.py\", line 2434, in _handle_dbapi_exception_noconnection\nraise sqlalchemy_exception.with_traceback(exc_info[2]) from e\nFile \"/var/task/sqlalchemy/engine/base.py\", line 143, in __init__\nself._dbapi_connection = engine.raw_connection()\n^^^^^^^^^^^^^^^^^^^^^^^\nFile \"/var/task/sqlalchemy/engine/base.py\", line 3295, in raw_connection\nreturn self.pool.connect()\n^^^^^^^^^^^^^^^^^^^\nFile \"/var/task/sqlalchemy/pool/base.py\", line 447, in connect\nreturn _ConnectionFairy._checkout(self)\n^^^^^^^^^^^^^^^^^^^^^^^^^^^^^^^^\nFile \"/var/task/sqlalchemy/pool/base.py\", line 1264, in _checkout\nfairy = _ConnectionRecord.checkout(pool)\n^^^^^^^^^^^^^^^^^^^^^^^^^^^^^^^^\nFile \"/var/task/sqlalchemy/pool/base.py\", line 711, in checkout\nrec = pool._do_get()\n^^^^^^^^^^^^^^\nFile \"/var/task/sqlalchemy/pool/impl.py\", line 177, in _do_get\nwith util.safe_reraise():\n^^^^^^^^^^^^^^^^^^^\nFile \"/var/task/sqlalchemy/util/langhelpers.py\", line 224, in __exit__\nraise exc_value.with_traceback(exc_tb)\nFile \"/var/task/sqlalchemy/pool/impl.py\", line 175, in _do_get\nreturn self._create_connection()\n^^^^^^^^^^^^^^^^^^^^^^^^^\nFile \"/var/task/sqlalchemy/pool/base.py\", line 388, in _create_connection\nreturn _ConnectionRecord(self)\n^^^^^^^^^^^^^^^^^^^^^^^\nFile \"/var/task/sqlalchemy/pool/base.py\", line 673, in __init__\nself.__connect()\nFile \"/var/task/sqlalchemy/pool/base.py\", line 899, in __connect\nwith util.safe_reraise():\n^^^^^^^^^^^^^^^^^^^\nFile \"/var/task/sqlalchemy/util/langhelpers.py\", line 224, in __exit__\nraise exc_value.with_traceback(exc_tb)\nFile \"/var/task/sqlalchemy/pool/base.py\", line 895, in __connect\nself.dbapi_connection = connection = pool._invoke_creator(self)\n^^^^^^^^^^^^^^^^^^^^^^^^^^\nFile \"/var/task/sqlalchemy/engine/create.py\", line 646, in connect\nreturn dialect.connect(*cargs, **cparams)\n^^^^^^^^^^^^^^^^^^^^^^^^^^^^^^^^^^\nFile \"/var/task/sqlalchemy/engine/default.py\", line 626, in connect\nreturn self.loaded_dbapi.connect(*cargs, **cparams)  # type: ignore[no-any-return]  # NOQA: E501\n^^^^^^^^^^^^^^^^^^^^^^^^^^^^^^^^^^^^^^^^^^^^\nFile \"/var/task/psycopg2/__init__.py\", line 122, in connect\nconn = _connect(dsn, connection_factory=connection_factory, **kwasync)\n^^^^^^^^^^^^^^^^^^^^^^^^^^^^^^^^^^^^^^^^^^^^^^^^^^^^^^^^^^^^^^^\nsqlalchemy.exc.OperationalError: (psycopg2.OperationalError) connection to server at \"db.ymmyielhidafnqvbsdra.supabase.co\" (2600:1f18:2e13:9d11:9819:684:a689:9dd9), port 5432 failed: Cannot assign requested address\nIs the server running on that host and accepting TCP/IP connections?\n(Background on this error at: https://sqlalche.me/e/20/e3q8)\nPython process exited with exit status: 1. The logs above can help with debugging the issue.","projectId":"prj_tQqdVztKk9tpelT7m49G7XNyEFrV","traceId":"","sessionId":"","invocationId":"01K21KNJ9TBAW44E6STCQSWC65","instanceId":"","concurrency":-1},{"TimeUTC":"2025-08-07 06:32:11","timestampInMs":1754548331474,"requestPath":"ai-checker-oy8mnk3j4-chris-anzilottis-projects.vercel.app/favicon.ico","requestMethod":"GET","requestQueryString":"","responseStatusCode":500,"requestId":"fzgjv-1754548331433-34759d280b56","requestUserAgent":"vercel-favicon/1.0","level":"error","environment":"production","branch":"master","vercelCache":"MISS","type":"lambda","function":"/api/index","host":"ai-checker-oy8mnk3j4-chris-anzilottis-projects.vercel.app","deploymentDomain":"ai-checker-oy8mnk3j4-chris-anzilottis-projects.vercel.app","deploymentId":"dpl_CevT8h1YNj63hdtAytibbLR52ZrV","durationMs":5975,"region":"iad1","maxMemoryUsed":239,"memorySize":2048,"message":"","projectId":"prj_tQqdVztKk9tpelT7m49G7XNyEFrV","traceId":"","sessionId":"","invocationId":"01K21KNRYJ7NHGNSA2PM5R3X67","instanceId":"","concurrency":1},{"TimeUTC":"2025-08-07 06:32:08","timestampInMs":1754548328898,"requestPath":"ai-checker-psi.vercel.app/","requestMethod":"GET","requestQueryString":"","responseStatusCode":500,"requestId":"w849m-1754548328847-de941ad3af76","requestUserAgent":"Mozilla/5.0 (Windows NT 10.0; Win64; x64) AppleWebKit/537.36 (KHTML, like Gecko) Chrome/138.0.0.0 Safari/537.36 Edg/138.0.0.0","level":"error","environment":"production","branch":"master","vercelCache":"MISS","type":"lambda","function":"/api/index","host":"ai-checker-psi.vercel.app","deploymentDomain":"ai-checker-psi.vercel.app","deploymentId":"dpl_CevT8h1YNj63hdtAytibbLR52ZrV","durationMs":5824,"region":"iad1","maxMemoryUsed":239,"memorySize":2048,"message":"","projectId":"prj_tQqdVztKk9tpelT7m49G7XNyEFrV","traceId":"","sessionId":"","invocationId":"01K21KNPE2ZTRJGXM13VDBN4VG","instanceId":"","concurrency":1},{"TimeUTC":"2025-08-07 06:32:08","timestampInMs":1754548328564,"requestPath":"ai-checker-oy8mnk3j4-chris-anzilottis-projects.vercel.app/","requestMethod":"GET","requestQueryString":"","responseStatusCode":500,"requestId":"d4ccd-1754548328506-11020a6aa571","requestUserAgent":"vercel-screenshot/1.0","level":"error","environment":"production","branch":"master","vercelCache":"MISS","type":"lambda","function":"/api/index","host":"ai-checker-oy8mnk3j4-chris-anzilottis-projects.vercel.app","deploymentDomain":"ai-checker-oy8mnk3j4-chris-anzilottis-projects.vercel.app","deploymentId":"dpl_CevT8h1YNj63hdtAytibbLR52ZrV","durationMs":6010,"region":"iad1","maxMemoryUsed":240,"memorySize":2048,"message":"","projectId":"prj_tQqdVztKk9tpelT7m49G7XNyEFrV","traceId":"","sessionId":"","invocationId":"01K21KNP3MN9D7A0PK9KKYBTTK","instanceId":"","concurrency":1},{"TimeUTC":"2025-08-07 06:32:08","timestampInMs":1754548328488,"requestPath":"ai-checker-oy8mnk3j4-chris-anzilottis-projects.vercel.app/","requestMethod":"GET","requestQueryString":"","responseStatusCode":500,"requestId":"5cdhg-1754548328446-f7fbb63f5d60","requestUserAgent":"vercel-screenshot/1.0","level":"error","environment":"production","branch":"master","vercelCache":"MISS","type":"lambda","function":"/api/index","host":"ai-checker-oy8mnk3j4-chris-anzilottis-projects.vercel.app","deploymentDomain":"ai-checker-oy8mnk3j4-chris-anzilottis-projects.vercel.app","deploymentId":"dpl_CevT8h1YNj63hdtAytibbLR52ZrV","durationMs":5871,"region":"iad1","maxMemoryUsed":239,"memorySize":2048,"message":"","projectId":"prj_tQqdVztKk9tpelT7m49G7XNyEFrV","traceId":"","sessionId":"","invocationId":"01K21KNP18WMJCCPHPKW7DGCT1","instanceId":"","concurrency":1},{"TimeUTC":"2025-08-07 06:32:08","timestampInMs":1754548328389,"requestPath":"ai-checker-oy8mnk3j4-chris-anzilottis-projects.vercel.app/","requestMethod":"GET","requestQueryString":"","responseStatusCode":500,"requestId":"mcp6l-1754548328350-641438ebbaa1","requestUserAgent":"vercel-favicon/1.0","level":"error","environment":"production","branch":"master","vercelCache":"MISS","type":"lambda","function":"/api/index","host":"ai-checker-oy8mnk3j4-chris-anzilottis-projects.vercel.app","deploymentDomain":"ai-checker-oy8mnk3j4-chris-anzilottis-projects.vercel.app","deploymentId":"dpl_CevT8h1YNj63hdtAytibbLR52ZrV","durationMs":5148,"region":"iad1","maxMemoryUsed":239,"memorySize":2048,"message":"","projectId":"prj_tQqdVztKk9tpelT7m49G7XNyEFrV","traceId":"","sessionId":"","invocationId":"01K21KNNY6HD01T4RMZQC3Q1JA","instanceId":"","concurrency":1},{"TimeUTC":"2025-08-07 06:32:04","timestampInMs":1754548324666,"requestPath":"ai-checker-oy8mnk3j4-chris-anzilottis-projects.vercel.app/","requestMethod":"GET","requestQueryString":"","responseStatusCode":500,"requestId":"wwgjx-1754548324479-f25676d21443","requestUserAgent":"vercel-favicon/1.0","level":"error","environment":"production","branch":"master","vercelCache":"MISS","type":"lambda","function":"/api/index","host":"ai-checker-oy8mnk3j4-chris-anzilottis-projects.vercel.app","deploymentDomain":"ai-checker-oy8mnk3j4-chris-anzilottis-projects.vercel.app","deploymentId":"dpl_CevT8h1YNj63hdtAytibbLR52ZrV","durationMs":5871,"region":"iad1","maxMemoryUsed":239,"memorySize":2048,"message":"","projectId":"prj_tQqdVztKk9tpelT7m49G7XNyEFrV","traceId":"","sessionId":"","invocationId":"01K21KNJ9TBAW44E6STCQSWC65","instanceId":"","concurrency":1},{"TimeUTC":"2025-08-07 06:32:04","timestampInMs":1754548324658,"requestPath":"ai-checker-oy8mnk3j4-chris-anzilottis-projects.vercel.app/","requestMethod":"GET","requestQueryString":"","responseStatusCode":500,"requestId":"xtqxh-1754548324384-5788700dd3cb","requestUserAgent":"vercel-screenshot/1.0","level":"error","environment":"production","branch":"master","vercelCache":"MISS","type":"lambda","function":"/api/index","host":"ai-checker-oy8mnk3j4-chris-anzilottis-projects.vercel.app","deploymentDomain":"ai-checker-oy8mnk3j4-chris-anzilottis-projects.vercel.app","deploymentId":"dpl_CevT8h1YNj63hdtAytibbLR52ZrV","durationMs":6061,"region":"iad1","maxMemoryUsed":240,"memorySize":2048,"message":"","projectId":"prj_tQqdVztKk9tpelT7m49G7XNyEFrV","traceId":"","sessionId":"","invocationId":"01K21KNJ9JJ3SEX1F0AR536VY3","instanceId":"","concurrency":1},{"TimeUTC":"2025-08-07 06:32:04","timestampInMs":1754548324657,"requestPath":"ai-checker-oy8mnk3j4-chris-anzilottis-projects.vercel.app/","requestMethod":"GET","requestQueryString":"","responseStatusCode":500,"requestId":"k5xm9-1754548324407-8fb55c5392c7","requestUserAgent":"vercel-favicon/1.0","level":"error","environment":"production","branch":"master","vercelCache":"MISS","type":"lambda","function":"/api/index","host":"ai-checker-oy8mnk3j4-chris-anzilottis-projects.vercel.app","deploymentDomain":"ai-checker-oy8mnk3j4-chris-anzilottis-projects.vercel.app","deploymentId":"dpl_CevT8h1YNj63hdtAytibbLR52ZrV","durationMs":6049,"region":"iad1","maxMemoryUsed":239,"memorySize":2048,"message":"","projectId":"prj_tQqdVztKk9tpelT7m49G7XNyEFrV","traceId":"","sessionId":"","invocationId":"01K21KNJ9HA60813MDBFP9MBTA","instanceId":"","concurrency":1},{"TimeUTC":"2025-08-07 06:32:04","timestampInMs":1754548324657,"requestPath":"ai-checker-oy8mnk3j4-chris-anzilottis-projects.vercel.app/","requestMethod":"GET","requestQueryString":"","responseStatusCode":500,"requestId":"qrhjr-1754548324402-b846e44d78a3","requestUserAgent":"vercel-screenshot/1.0","level":"error","environment":"production","branch":"master","vercelCache":"MISS","type":"lambda","function":"/api/index","host":"ai-checker-oy8mnk3j4-chris-anzilottis-projects.vercel.app","deploymentDomain":"ai-checker-oy8mnk3j4-chris-anzilottis-projects.vercel.app","deploymentId":"dpl_CevT8h1YNj63hdtAytibbLR52ZrV","durationMs":6115,"region":"iad1","maxMemoryUsed":241,"memorySize":2048,"message":"","projectId":"prj_tQqdVztKk9tpelT7m49G7XNyEFrV","traceId":"","sessionId":"","invocationId":"01K21KNJ9HA60813MDBHS4GG54","instanceId":"","concurrency":1}]